WARNING 2024-03-14 12:28:40,289 log 1248 8020 Not Found: /
WARNING 2024-03-14 12:28:40,710 log 1248 25460 Not Found: /favicon.ico
WARNING 2024-03-14 12:30:38,083 log 22548 25452 Not Found: /
WARNING 2024-03-14 12:32:12,618 log 17144 16652 Not Found: /
WARNING 2024-03-14 13:18:35,738 log 7452 24928 Not Found: /
WARNING 2024-03-18 21:12:56,642 log 19044 24008 Not Found: /
WARNING 2024-03-18 21:12:57,092 log 19044 23372 Not Found: /favicon.ico
WARNING 2024-03-18 21:13:07,476 log 19044 23372 Not Found: /shops
WARNING 2024-03-18 21:22:25,196 log 960 22828 Not Found: /
WARNING 2024-03-18 21:22:29,512 log 960 22828 Not Found: /shops
WARNING 2024-03-18 21:22:52,154 log 960 22828 Not Found: /shops
WARNING 2024-03-18 21:25:16,693 log 960 22828 Not Found: /shops
WARNING 2024-03-18 21:25:17,802 log 960 22828 Not Found: /shops
WARNING 2024-03-18 21:30:43,263 log 960 23148 Not Found: /shops
WARNING 2024-03-18 21:31:42,711 log 22372 11224 Not Found: /shops
WARNING 2024-03-19 12:42:09,137 log 21832 5376 Not Found: /favicon.ico
WARNING 2024-03-19 12:45:32,947 log 21832 13156 Not Found: /dashboard
WARNING 2024-03-19 12:45:43,823 log 21832 4080 Not Found: /favicon.ico
WARNING 2024-03-19 12:53:05,443 log 19380 9096 Bad Request: /admin/aggregator/product/
WARNING 2024-03-19 12:56:12,360 log 19380 15464 Not Found: /dashboard
WARNING 2024-03-19 12:58:35,768 log 19380 17104 Bad Request: /admin/aggregator/product/
WARNING 2024-03-19 12:59:13,101 log 3252 15920 Not Found: /dashboard
ERROR 2024-03-19 13:31:59,378 log 16012 23804 Internal Server Error: /admin/django_celery_beat/periodictask/3/change/
Traceback (most recent call last):
  File "c:\Users\Sergey Trosenko\DyplomaProductAggregator\.venv\Lib\site-packages\django\db\backends\utils.py", line 89, in _execute
    return self.cursor.execute(sql, params)
           ^^^^^^^^^^^^^^^^^^^^^^^^^^^^^^^^
  File "c:\Users\Sergey Trosenko\DyplomaProductAggregator\.venv\Lib\site-packages\django\db\backends\sqlite3\base.py", line 328, in execute
    return super().execute(query, params)
           ^^^^^^^^^^^^^^^^^^^^^^^^^^^^^^
sqlite3.OperationalError: database is locked

The above exception was the direct cause of the following exception:

Traceback (most recent call last):
  File "c:\Users\Sergey Trosenko\DyplomaProductAggregator\.venv\Lib\site-packages\django\core\handlers\exception.py", line 55, in inner
    response = get_response(request)
               ^^^^^^^^^^^^^^^^^^^^^
  File "c:\Users\Sergey Trosenko\DyplomaProductAggregator\.venv\Lib\site-packages\django\core\handlers\base.py", line 197, in _get_response
    response = wrapped_callback(request, *callback_args, **callback_kwargs)
               ^^^^^^^^^^^^^^^^^^^^^^^^^^^^^^^^^^^^^^^^^^^^^^^^^^^^^^^^^^^^
  File "c:\Users\Sergey Trosenko\DyplomaProductAggregator\.venv\Lib\site-packages\django\contrib\admin\options.py", line 688, in wrapper
    return self.admin_site.admin_view(view)(*args, **kwargs)
           ^^^^^^^^^^^^^^^^^^^^^^^^^^^^^^^^^^^^^^^^^^^^^^^^^
  File "c:\Users\Sergey Trosenko\DyplomaProductAggregator\.venv\Lib\site-packages\django\utils\decorators.py", line 134, in _wrapper_view
    response = view_func(request, *args, **kwargs)
               ^^^^^^^^^^^^^^^^^^^^^^^^^^^^^^^^^^^
  File "c:\Users\Sergey Trosenko\DyplomaProductAggregator\.venv\Lib\site-packages\django\views\decorators\cache.py", line 62, in _wrapper_view_func
    response = view_func(request, *args, **kwargs)
               ^^^^^^^^^^^^^^^^^^^^^^^^^^^^^^^^^^^
  File "c:\Users\Sergey Trosenko\DyplomaProductAggregator\.venv\Lib\site-packages\django\contrib\admin\sites.py", line 242, in inner
    return view(request, *args, **kwargs)
           ^^^^^^^^^^^^^^^^^^^^^^^^^^^^^^
  File "c:\Users\Sergey Trosenko\DyplomaProductAggregator\.venv\Lib\site-packages\django\contrib\admin\options.py", line 1889, in change_view
    return self.changeform_view(request, object_id, form_url, extra_context)
           ^^^^^^^^^^^^^^^^^^^^^^^^^^^^^^^^^^^^^^^^^^^^^^^^^^^^^^^^^^^^^^^^^
  File "c:\Users\Sergey Trosenko\DyplomaProductAggregator\.venv\Lib\site-packages\django_celery_beat\admin.py", line 158, in changeform_view
    return super().changeform_view(request, object_id,
           ^^^^^^^^^^^^^^^^^^^^^^^^^^^^^^^^^^^^^^^^^^^
  File "c:\Users\Sergey Trosenko\DyplomaProductAggregator\.venv\Lib\site-packages\django\utils\decorators.py", line 46, in _wrapper
    return bound_method(*args, **kwargs)
           ^^^^^^^^^^^^^^^^^^^^^^^^^^^^^
  File "c:\Users\Sergey Trosenko\DyplomaProductAggregator\.venv\Lib\site-packages\django\utils\decorators.py", line 134, in _wrapper_view
    response = view_func(request, *args, **kwargs)
               ^^^^^^^^^^^^^^^^^^^^^^^^^^^^^^^^^^^
  File "c:\Users\Sergey Trosenko\DyplomaProductAggregator\.venv\Lib\site-packages\django\contrib\admin\options.py", line 1747, in changeform_view
    return self._changeform_view(request, object_id, form_url, extra_context)
           ^^^^^^^^^^^^^^^^^^^^^^^^^^^^^^^^^^^^^^^^^^^^^^^^^^^^^^^^^^^^^^^^^^
  File "c:\Users\Sergey Trosenko\DyplomaProductAggregator\.venv\Lib\site-packages\django\contrib\admin\options.py", line 1798, in _changeform_view
    self.save_model(request, new_object, form, not add)
  File "c:\Users\Sergey Trosenko\DyplomaProductAggregator\.venv\Lib\site-packages\django\contrib\admin\options.py", line 1227, in save_model
    obj.save()
  File "c:\Users\Sergey Trosenko\DyplomaProductAggregator\.venv\Lib\site-packages\django_celery_beat\models.py", line 604, in save
    super().save(*args, **kwargs)
  File "c:\Users\Sergey Trosenko\DyplomaProductAggregator\.venv\Lib\site-packages\django\db\models\base.py", line 814, in save
    self.save_base(
  File "c:\Users\Sergey Trosenko\DyplomaProductAggregator\.venv\Lib\site-packages\django\db\models\base.py", line 861, in save_base
    pre_save.send(
  File "c:\Users\Sergey Trosenko\DyplomaProductAggregator\.venv\Lib\site-packages\django\dispatch\dispatcher.py", line 177, in send
    (receiver, receiver(signal=self, sender=sender, **named))
               ^^^^^^^^^^^^^^^^^^^^^^^^^^^^^^^^^^^^^^^^^^^^^
  File "c:\Users\Sergey Trosenko\DyplomaProductAggregator\.venv\Lib\site-packages\django_celery_beat\models.py", line 394, in changed
    cls.update_changed()
  File "c:\Users\Sergey Trosenko\DyplomaProductAggregator\.venv\Lib\site-packages\django_celery_beat\models.py", line 398, in update_changed
    cls.objects.update_or_create(ident=1, defaults={'last_update': now()})
  File "c:\Users\Sergey Trosenko\DyplomaProductAggregator\.venv\Lib\site-packages\django\db\models\manager.py", line 87, in manager_method
    return getattr(self.get_queryset(), name)(*args, **kwargs)
           ^^^^^^^^^^^^^^^^^^^^^^^^^^^^^^^^^^^^^^^^^^^^^^^^^^^
  File "c:\Users\Sergey Trosenko\DyplomaProductAggregator\.venv\Lib\site-packages\django\db\models\query.py", line 970, in update_or_create
    obj.save(using=self.db, update_fields=update_fields)
  File "c:\Users\Sergey Trosenko\DyplomaProductAggregator\.venv\Lib\site-packages\django\db\models\base.py", line 814, in save
    self.save_base(
  File "c:\Users\Sergey Trosenko\DyplomaProductAggregator\.venv\Lib\site-packages\django\db\models\base.py", line 877, in save_base
    updated = self._save_table(
              ^^^^^^^^^^^^^^^^^
  File "c:\Users\Sergey Trosenko\DyplomaProductAggregator\.venv\Lib\site-packages\django\db\models\base.py", line 990, in _save_table
    updated = self._do_update(
              ^^^^^^^^^^^^^^^^
  File "c:\Users\Sergey Trosenko\DyplomaProductAggregator\.venv\Lib\site-packages\django\db\models\base.py", line 1054, in _do_update
    return filtered._update(values) > 0
           ^^^^^^^^^^^^^^^^^^^^^^^^
  File "c:\Users\Sergey Trosenko\DyplomaProductAggregator\.venv\Lib\site-packages\django\db\models\query.py", line 1231, in _update
    return query.get_compiler(self.db).execute_sql(CURSOR)
           ^^^^^^^^^^^^^^^^^^^^^^^^^^^^^^^^^^^^^^^^^^^^^^^
  File "c:\Users\Sergey Trosenko\DyplomaProductAggregator\.venv\Lib\site-packages\django\db\models\sql\compiler.py", line 1982, in execute_sql
    cursor = super().execute_sql(result_type)
             ^^^^^^^^^^^^^^^^^^^^^^^^^^^^^^^^
  File "c:\Users\Sergey Trosenko\DyplomaProductAggregator\.venv\Lib\site-packages\django\db\models\sql\compiler.py", line 1560, in execute_sql
    cursor.execute(sql, params)
  File "c:\Users\Sergey Trosenko\DyplomaProductAggregator\.venv\Lib\site-packages\debug_toolbar\panels\sql\tracking.py", line 235, in execute
    return self._record(super().execute, sql, params)
           ^^^^^^^^^^^^^^^^^^^^^^^^^^^^^^^^^^^^^^^^^^
  File "c:\Users\Sergey Trosenko\DyplomaProductAggregator\.venv\Lib\site-packages\debug_toolbar\panels\sql\tracking.py", line 160, in _record
    return method(sql, params)
           ^^^^^^^^^^^^^^^^^^^
  File "c:\Users\Sergey Trosenko\DyplomaProductAggregator\.venv\Lib\site-packages\django\db\backends\utils.py", line 102, in execute
    return super().execute(sql, params)
           ^^^^^^^^^^^^^^^^^^^^^^^^^^^^
  File "c:\Users\Sergey Trosenko\DyplomaProductAggregator\.venv\Lib\site-packages\django\db\backends\utils.py", line 67, in execute
    return self._execute_with_wrappers(
           ^^^^^^^^^^^^^^^^^^^^^^^^^^^^
  File "c:\Users\Sergey Trosenko\DyplomaProductAggregator\.venv\Lib\site-packages\django\db\backends\utils.py", line 80, in _execute_with_wrappers
    return executor(sql, params, many, context)
           ^^^^^^^^^^^^^^^^^^^^^^^^^^^^^^^^^^^^
  File "c:\Users\Sergey Trosenko\DyplomaProductAggregator\.venv\Lib\site-packages\django\db\backends\utils.py", line 84, in _execute
    with self.db.wrap_database_errors:
  File "c:\Users\Sergey Trosenko\DyplomaProductAggregator\.venv\Lib\site-packages\django\db\utils.py", line 91, in __exit__
    raise dj_exc_value.with_traceback(traceback) from exc_value
  File "c:\Users\Sergey Trosenko\DyplomaProductAggregator\.venv\Lib\site-packages\django\db\backends\utils.py", line 89, in _execute
    return self.cursor.execute(sql, params)
           ^^^^^^^^^^^^^^^^^^^^^^^^^^^^^^^^
  File "c:\Users\Sergey Trosenko\DyplomaProductAggregator\.venv\Lib\site-packages\django\db\backends\sqlite3\base.py", line 328, in execute
    return super().execute(query, params)
           ^^^^^^^^^^^^^^^^^^^^^^^^^^^^^^
django.db.utils.OperationalError: database is locked
WARNING 2024-03-19 22:15:08,707 log 22300 16868 Not Found: /register
WARNING 2024-03-19 22:22:09,590 log 22300 23500 Not Found: /storage/images/empty_user.jpg
WARNING 2024-03-19 22:22:12,617 log 22300 18188 Not Found: /favicon.ico
WARNING 2024-03-19 22:22:14,675 log 22300 15716 Not Found: /storage/images/empty_user.jpg
WARNING 2024-03-19 22:22:33,803 log 22300 1720 Not Found: /favicon.ico
WARNING 2024-03-19 22:22:36,754 log 22300 1720 Not Found: /storage/images/empty_user.jpg
WARNING 2024-03-19 22:22:38,686 log 22300 1720 Not Found: /storage/images/empty_user.jpg
ERROR 2024-03-21 22:19:35,066 log 22472 17176 Internal Server Error: /graphql
Traceback (most recent call last):
  File "c:\Users\Sergey Trosenko\DyplomaProductAggregator\.venv\Lib\site-packages\django\core\handlers\exception.py", line 55, in inner
    response = get_response(request)
               ^^^^^^^^^^^^^^^^^^^^^
  File "c:\Users\Sergey Trosenko\DyplomaProductAggregator\.venv\Lib\site-packages\django\core\handlers\base.py", line 197, in _get_response
    response = wrapped_callback(request, *callback_args, **callback_kwargs)
               ^^^^^^^^^^^^^^^^^^^^^^^^^^^^^^^^^^^^^^^^^^^^^^^^^^^^^^^^^^^^
  File "c:\Users\Sergey Trosenko\DyplomaProductAggregator\.venv\Lib\site-packages\django\views\decorators\csrf.py", line 56, in wrapper_view
    return view_func(*args, **kwargs)
           ^^^^^^^^^^^^^^^^^^^^^^^^^^
  File "c:\Users\Sergey Trosenko\DyplomaProductAggregator\.venv\Lib\site-packages\django\views\generic\base.py", line 97, in view
    self = cls(**initkwargs)
           ^^^^^^^^^^^^^^^^^
  File "c:\Users\Sergey Trosenko\DyplomaProductAggregator\.venv\Lib\site-packages\graphene_django\views.py", line 114, in __init__
    schema = graphene_settings.SCHEMA
             ^^^^^^^^^^^^^^^^^^^^^^^^
  File "c:\Users\Sergey Trosenko\DyplomaProductAggregator\.venv\Lib\site-packages\graphene_django\settings.py", line 127, in __getattr__
    val = perform_import(val, attr)
          ^^^^^^^^^^^^^^^^^^^^^^^^^
  File "c:\Users\Sergey Trosenko\DyplomaProductAggregator\.venv\Lib\site-packages\graphene_django\settings.py", line 66, in perform_import
    return import_from_string(val, setting_name)
           ^^^^^^^^^^^^^^^^^^^^^^^^^^^^^^^^^^^^^
  File "c:\Users\Sergey Trosenko\DyplomaProductAggregator\.venv\Lib\site-packages\graphene_django\settings.py", line 80, in import_from_string
    module = importlib.import_module(module_path)
             ^^^^^^^^^^^^^^^^^^^^^^^^^^^^^^^^^^^^
  File "c:\Users\Sergey Trosenko\AppData\Local\Programs\Python\Python312\Lib\importlib\__init__.py", line 90, in import_module
    return _bootstrap._gcd_import(name[level:], package, level)
           ^^^^^^^^^^^^^^^^^^^^^^^^^^^^^^^^^^^^^^^^^^^^^^^^^^^^
  File "<frozen importlib._bootstrap>", line 1381, in _gcd_import
  File "<frozen importlib._bootstrap>", line 1354, in _find_and_load
  File "<frozen importlib._bootstrap>", line 1325, in _find_and_load_unlocked
  File "<frozen importlib._bootstrap>", line 929, in _load_unlocked
  File "<frozen importlib._bootstrap_external>", line 994, in exec_module
  File "<frozen importlib._bootstrap>", line 488, in _call_with_frames_removed
  File "C:\Users\Sergey Trosenko\DyplomaProductAggregator\backend\backend\schema.py", line 4, in <module>
    import users.schema
  File "C:\Users\Sergey Trosenko\DyplomaProductAggregator\backend\users\schema.py", line 12, in <module>
    class ProfileType(DjangoObjectType):
  File "c:\Users\Sergey Trosenko\DyplomaProductAggregator\.venv\Lib\site-packages\graphene\types\objecttype.py", line 30, in __new__
    base_cls = super().__new__(
               ^^^^^^^^^^^^^^^^
  File "c:\Users\Sergey Trosenko\DyplomaProductAggregator\.venv\Lib\site-packages\graphene\utils\subclass_with_meta.py", line 46, in __init_subclass__
    super_class.__init_subclass_with_meta__(**options)
  File "c:\Users\Sergey Trosenko\DyplomaProductAggregator\.venv\Lib\site-packages\graphene_django\types.py", line 153, in __init_subclass_with_meta__
    assert is_valid_django_model(model), (
AssertionError: You need to pass a valid Django Model in ProfileType.Meta, received "None".
ERROR 2024-03-21 22:23:19,361 log 22472 17176 Internal Server Error: /graphql
Traceback (most recent call last):
  File "c:\Users\Sergey Trosenko\DyplomaProductAggregator\.venv\Lib\site-packages\django\core\handlers\exception.py", line 55, in inner
    response = get_response(request)
               ^^^^^^^^^^^^^^^^^^^^^
  File "c:\Users\Sergey Trosenko\DyplomaProductAggregator\.venv\Lib\site-packages\django\core\handlers\base.py", line 197, in _get_response
    response = wrapped_callback(request, *callback_args, **callback_kwargs)
               ^^^^^^^^^^^^^^^^^^^^^^^^^^^^^^^^^^^^^^^^^^^^^^^^^^^^^^^^^^^^
  File "c:\Users\Sergey Trosenko\DyplomaProductAggregator\.venv\Lib\site-packages\django\views\decorators\csrf.py", line 56, in wrapper_view
    return view_func(*args, **kwargs)
           ^^^^^^^^^^^^^^^^^^^^^^^^^^
  File "c:\Users\Sergey Trosenko\DyplomaProductAggregator\.venv\Lib\site-packages\django\views\generic\base.py", line 97, in view
    self = cls(**initkwargs)
           ^^^^^^^^^^^^^^^^^
  File "c:\Users\Sergey Trosenko\DyplomaProductAggregator\.venv\Lib\site-packages\graphene_django\views.py", line 114, in __init__
    schema = graphene_settings.SCHEMA
             ^^^^^^^^^^^^^^^^^^^^^^^^
  File "c:\Users\Sergey Trosenko\DyplomaProductAggregator\.venv\Lib\site-packages\graphene_django\settings.py", line 127, in __getattr__
    val = perform_import(val, attr)
          ^^^^^^^^^^^^^^^^^^^^^^^^^
  File "c:\Users\Sergey Trosenko\DyplomaProductAggregator\.venv\Lib\site-packages\graphene_django\settings.py", line 66, in perform_import
    return import_from_string(val, setting_name)
           ^^^^^^^^^^^^^^^^^^^^^^^^^^^^^^^^^^^^^
  File "c:\Users\Sergey Trosenko\DyplomaProductAggregator\.venv\Lib\site-packages\graphene_django\settings.py", line 80, in import_from_string
    module = importlib.import_module(module_path)
             ^^^^^^^^^^^^^^^^^^^^^^^^^^^^^^^^^^^^
  File "c:\Users\Sergey Trosenko\AppData\Local\Programs\Python\Python312\Lib\importlib\__init__.py", line 90, in import_module
    return _bootstrap._gcd_import(name[level:], package, level)
           ^^^^^^^^^^^^^^^^^^^^^^^^^^^^^^^^^^^^^^^^^^^^^^^^^^^^
  File "<frozen importlib._bootstrap>", line 1381, in _gcd_import
  File "<frozen importlib._bootstrap>", line 1354, in _find_and_load
  File "<frozen importlib._bootstrap>", line 1325, in _find_and_load_unlocked
  File "<frozen importlib._bootstrap>", line 929, in _load_unlocked
  File "<frozen importlib._bootstrap_external>", line 994, in exec_module
  File "<frozen importlib._bootstrap>", line 488, in _call_with_frames_removed
  File "C:\Users\Sergey Trosenko\DyplomaProductAggregator\backend\backend\schema.py", line 4, in <module>
    import users.schema
  File "C:\Users\Sergey Trosenko\DyplomaProductAggregator\backend\users\schema.py", line 12, in <module>
    class ProfileType(DjangoObjectType):
  File "c:\Users\Sergey Trosenko\DyplomaProductAggregator\.venv\Lib\site-packages\graphene\types\objecttype.py", line 30, in __new__
    base_cls = super().__new__(
               ^^^^^^^^^^^^^^^^
  File "c:\Users\Sergey Trosenko\DyplomaProductAggregator\.venv\Lib\site-packages\graphene\utils\subclass_with_meta.py", line 46, in __init_subclass__
    super_class.__init_subclass_with_meta__(**options)
  File "c:\Users\Sergey Trosenko\DyplomaProductAggregator\.venv\Lib\site-packages\graphene_django\types.py", line 153, in __init_subclass_with_meta__
    assert is_valid_django_model(model), (
AssertionError: You need to pass a valid Django Model in ProfileType.Meta, received "None".
ERROR 2024-03-21 22:23:26,920 log 22472 17176 Internal Server Error: /graphql
Traceback (most recent call last):
  File "c:\Users\Sergey Trosenko\DyplomaProductAggregator\.venv\Lib\site-packages\django\core\handlers\exception.py", line 55, in inner
    response = get_response(request)
               ^^^^^^^^^^^^^^^^^^^^^
  File "c:\Users\Sergey Trosenko\DyplomaProductAggregator\.venv\Lib\site-packages\django\core\handlers\base.py", line 197, in _get_response
    response = wrapped_callback(request, *callback_args, **callback_kwargs)
               ^^^^^^^^^^^^^^^^^^^^^^^^^^^^^^^^^^^^^^^^^^^^^^^^^^^^^^^^^^^^
  File "c:\Users\Sergey Trosenko\DyplomaProductAggregator\.venv\Lib\site-packages\django\views\decorators\csrf.py", line 56, in wrapper_view
    return view_func(*args, **kwargs)
           ^^^^^^^^^^^^^^^^^^^^^^^^^^
  File "c:\Users\Sergey Trosenko\DyplomaProductAggregator\.venv\Lib\site-packages\django\views\generic\base.py", line 97, in view
    self = cls(**initkwargs)
           ^^^^^^^^^^^^^^^^^
  File "c:\Users\Sergey Trosenko\DyplomaProductAggregator\.venv\Lib\site-packages\graphene_django\views.py", line 114, in __init__
    schema = graphene_settings.SCHEMA
             ^^^^^^^^^^^^^^^^^^^^^^^^
  File "c:\Users\Sergey Trosenko\DyplomaProductAggregator\.venv\Lib\site-packages\graphene_django\settings.py", line 127, in __getattr__
    val = perform_import(val, attr)
          ^^^^^^^^^^^^^^^^^^^^^^^^^
  File "c:\Users\Sergey Trosenko\DyplomaProductAggregator\.venv\Lib\site-packages\graphene_django\settings.py", line 66, in perform_import
    return import_from_string(val, setting_name)
           ^^^^^^^^^^^^^^^^^^^^^^^^^^^^^^^^^^^^^
  File "c:\Users\Sergey Trosenko\DyplomaProductAggregator\.venv\Lib\site-packages\graphene_django\settings.py", line 80, in import_from_string
    module = importlib.import_module(module_path)
             ^^^^^^^^^^^^^^^^^^^^^^^^^^^^^^^^^^^^
  File "c:\Users\Sergey Trosenko\AppData\Local\Programs\Python\Python312\Lib\importlib\__init__.py", line 90, in import_module
    return _bootstrap._gcd_import(name[level:], package, level)
           ^^^^^^^^^^^^^^^^^^^^^^^^^^^^^^^^^^^^^^^^^^^^^^^^^^^^
  File "<frozen importlib._bootstrap>", line 1381, in _gcd_import
  File "<frozen importlib._bootstrap>", line 1354, in _find_and_load
  File "<frozen importlib._bootstrap>", line 1325, in _find_and_load_unlocked
  File "<frozen importlib._bootstrap>", line 929, in _load_unlocked
  File "<frozen importlib._bootstrap_external>", line 994, in exec_module
  File "<frozen importlib._bootstrap>", line 488, in _call_with_frames_removed
  File "C:\Users\Sergey Trosenko\DyplomaProductAggregator\backend\backend\schema.py", line 4, in <module>
    import users.schema
  File "C:\Users\Sergey Trosenko\DyplomaProductAggregator\backend\users\schema.py", line 12, in <module>
    class ProfileType(DjangoObjectType):
  File "c:\Users\Sergey Trosenko\DyplomaProductAggregator\.venv\Lib\site-packages\graphene\types\objecttype.py", line 30, in __new__
    base_cls = super().__new__(
               ^^^^^^^^^^^^^^^^
  File "c:\Users\Sergey Trosenko\DyplomaProductAggregator\.venv\Lib\site-packages\graphene\utils\subclass_with_meta.py", line 46, in __init_subclass__
    super_class.__init_subclass_with_meta__(**options)
  File "c:\Users\Sergey Trosenko\DyplomaProductAggregator\.venv\Lib\site-packages\graphene_django\types.py", line 153, in __init_subclass_with_meta__
    assert is_valid_django_model(model), (
AssertionError: You need to pass a valid Django Model in ProfileType.Meta, received "None".
ERROR 2024-03-21 22:23:28,484 log 22472 17176 Internal Server Error: /graphql
Traceback (most recent call last):
  File "c:\Users\Sergey Trosenko\DyplomaProductAggregator\.venv\Lib\site-packages\django\core\handlers\exception.py", line 55, in inner
    response = get_response(request)
               ^^^^^^^^^^^^^^^^^^^^^
  File "c:\Users\Sergey Trosenko\DyplomaProductAggregator\.venv\Lib\site-packages\django\core\handlers\base.py", line 197, in _get_response
    response = wrapped_callback(request, *callback_args, **callback_kwargs)
               ^^^^^^^^^^^^^^^^^^^^^^^^^^^^^^^^^^^^^^^^^^^^^^^^^^^^^^^^^^^^
  File "c:\Users\Sergey Trosenko\DyplomaProductAggregator\.venv\Lib\site-packages\django\views\decorators\csrf.py", line 56, in wrapper_view
    return view_func(*args, **kwargs)
           ^^^^^^^^^^^^^^^^^^^^^^^^^^
  File "c:\Users\Sergey Trosenko\DyplomaProductAggregator\.venv\Lib\site-packages\django\views\generic\base.py", line 97, in view
    self = cls(**initkwargs)
           ^^^^^^^^^^^^^^^^^
  File "c:\Users\Sergey Trosenko\DyplomaProductAggregator\.venv\Lib\site-packages\graphene_django\views.py", line 114, in __init__
    schema = graphene_settings.SCHEMA
             ^^^^^^^^^^^^^^^^^^^^^^^^
  File "c:\Users\Sergey Trosenko\DyplomaProductAggregator\.venv\Lib\site-packages\graphene_django\settings.py", line 127, in __getattr__
    val = perform_import(val, attr)
          ^^^^^^^^^^^^^^^^^^^^^^^^^
  File "c:\Users\Sergey Trosenko\DyplomaProductAggregator\.venv\Lib\site-packages\graphene_django\settings.py", line 66, in perform_import
    return import_from_string(val, setting_name)
           ^^^^^^^^^^^^^^^^^^^^^^^^^^^^^^^^^^^^^
  File "c:\Users\Sergey Trosenko\DyplomaProductAggregator\.venv\Lib\site-packages\graphene_django\settings.py", line 80, in import_from_string
    module = importlib.import_module(module_path)
             ^^^^^^^^^^^^^^^^^^^^^^^^^^^^^^^^^^^^
  File "c:\Users\Sergey Trosenko\AppData\Local\Programs\Python\Python312\Lib\importlib\__init__.py", line 90, in import_module
    return _bootstrap._gcd_import(name[level:], package, level)
           ^^^^^^^^^^^^^^^^^^^^^^^^^^^^^^^^^^^^^^^^^^^^^^^^^^^^
  File "<frozen importlib._bootstrap>", line 1381, in _gcd_import
  File "<frozen importlib._bootstrap>", line 1354, in _find_and_load
  File "<frozen importlib._bootstrap>", line 1325, in _find_and_load_unlocked
  File "<frozen importlib._bootstrap>", line 929, in _load_unlocked
  File "<frozen importlib._bootstrap_external>", line 994, in exec_module
  File "<frozen importlib._bootstrap>", line 488, in _call_with_frames_removed
  File "C:\Users\Sergey Trosenko\DyplomaProductAggregator\backend\backend\schema.py", line 4, in <module>
    import users.schema
  File "C:\Users\Sergey Trosenko\DyplomaProductAggregator\backend\users\schema.py", line 12, in <module>
    class ProfileType(DjangoObjectType):
  File "c:\Users\Sergey Trosenko\DyplomaProductAggregator\.venv\Lib\site-packages\graphene\types\objecttype.py", line 30, in __new__
    base_cls = super().__new__(
               ^^^^^^^^^^^^^^^^
  File "c:\Users\Sergey Trosenko\DyplomaProductAggregator\.venv\Lib\site-packages\graphene\utils\subclass_with_meta.py", line 46, in __init_subclass__
    super_class.__init_subclass_with_meta__(**options)
  File "c:\Users\Sergey Trosenko\DyplomaProductAggregator\.venv\Lib\site-packages\graphene_django\types.py", line 153, in __init_subclass_with_meta__
    assert is_valid_django_model(model), (
AssertionError: You need to pass a valid Django Model in ProfileType.Meta, received "None".
ERROR 2024-03-21 22:23:43,190 log 22472 17176 Internal Server Error: /graphql
Traceback (most recent call last):
  File "c:\Users\Sergey Trosenko\DyplomaProductAggregator\.venv\Lib\site-packages\django\core\handlers\exception.py", line 55, in inner
    response = get_response(request)
               ^^^^^^^^^^^^^^^^^^^^^
  File "c:\Users\Sergey Trosenko\DyplomaProductAggregator\.venv\Lib\site-packages\django\core\handlers\base.py", line 197, in _get_response
    response = wrapped_callback(request, *callback_args, **callback_kwargs)
               ^^^^^^^^^^^^^^^^^^^^^^^^^^^^^^^^^^^^^^^^^^^^^^^^^^^^^^^^^^^^
  File "c:\Users\Sergey Trosenko\DyplomaProductAggregator\.venv\Lib\site-packages\django\views\decorators\csrf.py", line 56, in wrapper_view
    return view_func(*args, **kwargs)
           ^^^^^^^^^^^^^^^^^^^^^^^^^^
  File "c:\Users\Sergey Trosenko\DyplomaProductAggregator\.venv\Lib\site-packages\django\views\generic\base.py", line 97, in view
    self = cls(**initkwargs)
           ^^^^^^^^^^^^^^^^^
  File "c:\Users\Sergey Trosenko\DyplomaProductAggregator\.venv\Lib\site-packages\graphene_django\views.py", line 114, in __init__
    schema = graphene_settings.SCHEMA
             ^^^^^^^^^^^^^^^^^^^^^^^^
  File "c:\Users\Sergey Trosenko\DyplomaProductAggregator\.venv\Lib\site-packages\graphene_django\settings.py", line 127, in __getattr__
    val = perform_import(val, attr)
          ^^^^^^^^^^^^^^^^^^^^^^^^^
  File "c:\Users\Sergey Trosenko\DyplomaProductAggregator\.venv\Lib\site-packages\graphene_django\settings.py", line 66, in perform_import
    return import_from_string(val, setting_name)
           ^^^^^^^^^^^^^^^^^^^^^^^^^^^^^^^^^^^^^
  File "c:\Users\Sergey Trosenko\DyplomaProductAggregator\.venv\Lib\site-packages\graphene_django\settings.py", line 80, in import_from_string
    module = importlib.import_module(module_path)
             ^^^^^^^^^^^^^^^^^^^^^^^^^^^^^^^^^^^^
  File "c:\Users\Sergey Trosenko\AppData\Local\Programs\Python\Python312\Lib\importlib\__init__.py", line 90, in import_module
    return _bootstrap._gcd_import(name[level:], package, level)
           ^^^^^^^^^^^^^^^^^^^^^^^^^^^^^^^^^^^^^^^^^^^^^^^^^^^^
  File "<frozen importlib._bootstrap>", line 1381, in _gcd_import
  File "<frozen importlib._bootstrap>", line 1354, in _find_and_load
  File "<frozen importlib._bootstrap>", line 1325, in _find_and_load_unlocked
  File "<frozen importlib._bootstrap>", line 929, in _load_unlocked
  File "<frozen importlib._bootstrap_external>", line 994, in exec_module
  File "<frozen importlib._bootstrap>", line 488, in _call_with_frames_removed
  File "C:\Users\Sergey Trosenko\DyplomaProductAggregator\backend\backend\schema.py", line 4, in <module>
    import users.schema
  File "C:\Users\Sergey Trosenko\DyplomaProductAggregator\backend\users\schema.py", line 12, in <module>
    class ProfileType(DjangoObjectType):
  File "c:\Users\Sergey Trosenko\DyplomaProductAggregator\.venv\Lib\site-packages\graphene\types\objecttype.py", line 30, in __new__
    base_cls = super().__new__(
               ^^^^^^^^^^^^^^^^
  File "c:\Users\Sergey Trosenko\DyplomaProductAggregator\.venv\Lib\site-packages\graphene\utils\subclass_with_meta.py", line 46, in __init_subclass__
    super_class.__init_subclass_with_meta__(**options)
  File "c:\Users\Sergey Trosenko\DyplomaProductAggregator\.venv\Lib\site-packages\graphene_django\types.py", line 153, in __init_subclass_with_meta__
    assert is_valid_django_model(model), (
AssertionError: You need to pass a valid Django Model in ProfileType.Meta, received "None".
ERROR 2024-03-21 22:24:26,628 log 22472 17176 Internal Server Error: /graphql
Traceback (most recent call last):
  File "c:\Users\Sergey Trosenko\DyplomaProductAggregator\.venv\Lib\site-packages\django\core\handlers\exception.py", line 55, in inner
    response = get_response(request)
               ^^^^^^^^^^^^^^^^^^^^^
  File "c:\Users\Sergey Trosenko\DyplomaProductAggregator\.venv\Lib\site-packages\django\core\handlers\base.py", line 197, in _get_response
    response = wrapped_callback(request, *callback_args, **callback_kwargs)
               ^^^^^^^^^^^^^^^^^^^^^^^^^^^^^^^^^^^^^^^^^^^^^^^^^^^^^^^^^^^^
  File "c:\Users\Sergey Trosenko\DyplomaProductAggregator\.venv\Lib\site-packages\django\views\decorators\csrf.py", line 56, in wrapper_view
    return view_func(*args, **kwargs)
           ^^^^^^^^^^^^^^^^^^^^^^^^^^
  File "c:\Users\Sergey Trosenko\DyplomaProductAggregator\.venv\Lib\site-packages\django\views\generic\base.py", line 97, in view
    self = cls(**initkwargs)
           ^^^^^^^^^^^^^^^^^
  File "c:\Users\Sergey Trosenko\DyplomaProductAggregator\.venv\Lib\site-packages\graphene_django\views.py", line 114, in __init__
    schema = graphene_settings.SCHEMA
             ^^^^^^^^^^^^^^^^^^^^^^^^
  File "c:\Users\Sergey Trosenko\DyplomaProductAggregator\.venv\Lib\site-packages\graphene_django\settings.py", line 127, in __getattr__
    val = perform_import(val, attr)
          ^^^^^^^^^^^^^^^^^^^^^^^^^
  File "c:\Users\Sergey Trosenko\DyplomaProductAggregator\.venv\Lib\site-packages\graphene_django\settings.py", line 66, in perform_import
    return import_from_string(val, setting_name)
           ^^^^^^^^^^^^^^^^^^^^^^^^^^^^^^^^^^^^^
  File "c:\Users\Sergey Trosenko\DyplomaProductAggregator\.venv\Lib\site-packages\graphene_django\settings.py", line 80, in import_from_string
    module = importlib.import_module(module_path)
             ^^^^^^^^^^^^^^^^^^^^^^^^^^^^^^^^^^^^
  File "c:\Users\Sergey Trosenko\AppData\Local\Programs\Python\Python312\Lib\importlib\__init__.py", line 90, in import_module
    return _bootstrap._gcd_import(name[level:], package, level)
           ^^^^^^^^^^^^^^^^^^^^^^^^^^^^^^^^^^^^^^^^^^^^^^^^^^^^
  File "<frozen importlib._bootstrap>", line 1381, in _gcd_import
  File "<frozen importlib._bootstrap>", line 1354, in _find_and_load
  File "<frozen importlib._bootstrap>", line 1325, in _find_and_load_unlocked
  File "<frozen importlib._bootstrap>", line 929, in _load_unlocked
  File "<frozen importlib._bootstrap_external>", line 994, in exec_module
  File "<frozen importlib._bootstrap>", line 488, in _call_with_frames_removed
  File "C:\Users\Sergey Trosenko\DyplomaProductAggregator\backend\backend\schema.py", line 4, in <module>
    import users.schema
  File "C:\Users\Sergey Trosenko\DyplomaProductAggregator\backend\users\schema.py", line 12, in <module>
    class ProfileType(DjangoObjectType):
  File "c:\Users\Sergey Trosenko\DyplomaProductAggregator\.venv\Lib\site-packages\graphene\types\objecttype.py", line 30, in __new__
    base_cls = super().__new__(
               ^^^^^^^^^^^^^^^^
  File "c:\Users\Sergey Trosenko\DyplomaProductAggregator\.venv\Lib\site-packages\graphene\utils\subclass_with_meta.py", line 46, in __init_subclass__
    super_class.__init_subclass_with_meta__(**options)
  File "c:\Users\Sergey Trosenko\DyplomaProductAggregator\.venv\Lib\site-packages\graphene_django\types.py", line 153, in __init_subclass_with_meta__
    assert is_valid_django_model(model), (
AssertionError: You need to pass a valid Django Model in ProfileType.Meta, received "None".
ERROR 2024-03-21 22:24:59,622 log 22472 17176 Internal Server Error: /graphql
Traceback (most recent call last):
  File "c:\Users\Sergey Trosenko\DyplomaProductAggregator\.venv\Lib\site-packages\django\core\handlers\exception.py", line 55, in inner
    response = get_response(request)
               ^^^^^^^^^^^^^^^^^^^^^
  File "c:\Users\Sergey Trosenko\DyplomaProductAggregator\.venv\Lib\site-packages\django\core\handlers\base.py", line 197, in _get_response
    response = wrapped_callback(request, *callback_args, **callback_kwargs)
               ^^^^^^^^^^^^^^^^^^^^^^^^^^^^^^^^^^^^^^^^^^^^^^^^^^^^^^^^^^^^
  File "c:\Users\Sergey Trosenko\DyplomaProductAggregator\.venv\Lib\site-packages\django\views\decorators\csrf.py", line 56, in wrapper_view
    return view_func(*args, **kwargs)
           ^^^^^^^^^^^^^^^^^^^^^^^^^^
  File "c:\Users\Sergey Trosenko\DyplomaProductAggregator\.venv\Lib\site-packages\django\views\generic\base.py", line 97, in view
    self = cls(**initkwargs)
           ^^^^^^^^^^^^^^^^^
  File "c:\Users\Sergey Trosenko\DyplomaProductAggregator\.venv\Lib\site-packages\graphene_django\views.py", line 114, in __init__
    schema = graphene_settings.SCHEMA
             ^^^^^^^^^^^^^^^^^^^^^^^^
  File "c:\Users\Sergey Trosenko\DyplomaProductAggregator\.venv\Lib\site-packages\graphene_django\settings.py", line 127, in __getattr__
    val = perform_import(val, attr)
          ^^^^^^^^^^^^^^^^^^^^^^^^^
  File "c:\Users\Sergey Trosenko\DyplomaProductAggregator\.venv\Lib\site-packages\graphene_django\settings.py", line 66, in perform_import
    return import_from_string(val, setting_name)
           ^^^^^^^^^^^^^^^^^^^^^^^^^^^^^^^^^^^^^
  File "c:\Users\Sergey Trosenko\DyplomaProductAggregator\.venv\Lib\site-packages\graphene_django\settings.py", line 80, in import_from_string
    module = importlib.import_module(module_path)
             ^^^^^^^^^^^^^^^^^^^^^^^^^^^^^^^^^^^^
  File "c:\Users\Sergey Trosenko\AppData\Local\Programs\Python\Python312\Lib\importlib\__init__.py", line 90, in import_module
    return _bootstrap._gcd_import(name[level:], package, level)
           ^^^^^^^^^^^^^^^^^^^^^^^^^^^^^^^^^^^^^^^^^^^^^^^^^^^^
  File "<frozen importlib._bootstrap>", line 1381, in _gcd_import
  File "<frozen importlib._bootstrap>", line 1354, in _find_and_load
  File "<frozen importlib._bootstrap>", line 1325, in _find_and_load_unlocked
  File "<frozen importlib._bootstrap>", line 929, in _load_unlocked
  File "<frozen importlib._bootstrap_external>", line 994, in exec_module
  File "<frozen importlib._bootstrap>", line 488, in _call_with_frames_removed
  File "C:\Users\Sergey Trosenko\DyplomaProductAggregator\backend\backend\schema.py", line 4, in <module>
    import users.schema
  File "C:\Users\Sergey Trosenko\DyplomaProductAggregator\backend\users\schema.py", line 12, in <module>
    class ProfileType(DjangoObjectType):
  File "c:\Users\Sergey Trosenko\DyplomaProductAggregator\.venv\Lib\site-packages\graphene\types\objecttype.py", line 30, in __new__
    base_cls = super().__new__(
               ^^^^^^^^^^^^^^^^
  File "c:\Users\Sergey Trosenko\DyplomaProductAggregator\.venv\Lib\site-packages\graphene\utils\subclass_with_meta.py", line 46, in __init_subclass__
    super_class.__init_subclass_with_meta__(**options)
  File "c:\Users\Sergey Trosenko\DyplomaProductAggregator\.venv\Lib\site-packages\graphene_django\types.py", line 153, in __init_subclass_with_meta__
    assert is_valid_django_model(model), (
AssertionError: You need to pass a valid Django Model in ProfileType.Meta, received "None".
ERROR 2024-03-21 22:25:17,819 log 22472 17176 Internal Server Error: /graphql
Traceback (most recent call last):
  File "c:\Users\Sergey Trosenko\DyplomaProductAggregator\.venv\Lib\site-packages\django\core\handlers\exception.py", line 55, in inner
    response = get_response(request)
               ^^^^^^^^^^^^^^^^^^^^^
  File "c:\Users\Sergey Trosenko\DyplomaProductAggregator\.venv\Lib\site-packages\django\core\handlers\base.py", line 197, in _get_response
    response = wrapped_callback(request, *callback_args, **callback_kwargs)
               ^^^^^^^^^^^^^^^^^^^^^^^^^^^^^^^^^^^^^^^^^^^^^^^^^^^^^^^^^^^^
  File "c:\Users\Sergey Trosenko\DyplomaProductAggregator\.venv\Lib\site-packages\django\views\decorators\csrf.py", line 56, in wrapper_view
    return view_func(*args, **kwargs)
           ^^^^^^^^^^^^^^^^^^^^^^^^^^
  File "c:\Users\Sergey Trosenko\DyplomaProductAggregator\.venv\Lib\site-packages\django\views\generic\base.py", line 97, in view
    self = cls(**initkwargs)
           ^^^^^^^^^^^^^^^^^
  File "c:\Users\Sergey Trosenko\DyplomaProductAggregator\.venv\Lib\site-packages\graphene_django\views.py", line 114, in __init__
    schema = graphene_settings.SCHEMA
             ^^^^^^^^^^^^^^^^^^^^^^^^
  File "c:\Users\Sergey Trosenko\DyplomaProductAggregator\.venv\Lib\site-packages\graphene_django\settings.py", line 127, in __getattr__
    val = perform_import(val, attr)
          ^^^^^^^^^^^^^^^^^^^^^^^^^
  File "c:\Users\Sergey Trosenko\DyplomaProductAggregator\.venv\Lib\site-packages\graphene_django\settings.py", line 66, in perform_import
    return import_from_string(val, setting_name)
           ^^^^^^^^^^^^^^^^^^^^^^^^^^^^^^^^^^^^^
  File "c:\Users\Sergey Trosenko\DyplomaProductAggregator\.venv\Lib\site-packages\graphene_django\settings.py", line 80, in import_from_string
    module = importlib.import_module(module_path)
             ^^^^^^^^^^^^^^^^^^^^^^^^^^^^^^^^^^^^
  File "c:\Users\Sergey Trosenko\AppData\Local\Programs\Python\Python312\Lib\importlib\__init__.py", line 90, in import_module
    return _bootstrap._gcd_import(name[level:], package, level)
           ^^^^^^^^^^^^^^^^^^^^^^^^^^^^^^^^^^^^^^^^^^^^^^^^^^^^
  File "<frozen importlib._bootstrap>", line 1381, in _gcd_import
  File "<frozen importlib._bootstrap>", line 1354, in _find_and_load
  File "<frozen importlib._bootstrap>", line 1325, in _find_and_load_unlocked
  File "<frozen importlib._bootstrap>", line 929, in _load_unlocked
  File "<frozen importlib._bootstrap_external>", line 994, in exec_module
  File "<frozen importlib._bootstrap>", line 488, in _call_with_frames_removed
  File "C:\Users\Sergey Trosenko\DyplomaProductAggregator\backend\backend\schema.py", line 4, in <module>
    import users.schema
  File "C:\Users\Sergey Trosenko\DyplomaProductAggregator\backend\users\schema.py", line 12, in <module>
    class ProfileType(DjangoObjectType):
  File "c:\Users\Sergey Trosenko\DyplomaProductAggregator\.venv\Lib\site-packages\graphene\types\objecttype.py", line 30, in __new__
    base_cls = super().__new__(
               ^^^^^^^^^^^^^^^^
  File "c:\Users\Sergey Trosenko\DyplomaProductAggregator\.venv\Lib\site-packages\graphene\utils\subclass_with_meta.py", line 46, in __init_subclass__
    super_class.__init_subclass_with_meta__(**options)
  File "c:\Users\Sergey Trosenko\DyplomaProductAggregator\.venv\Lib\site-packages\graphene_django\types.py", line 153, in __init_subclass_with_meta__
    assert is_valid_django_model(model), (
AssertionError: You need to pass a valid Django Model in ProfileType.Meta, received "None".
WARNING 2024-03-21 22:25:41,955 log 22472 19200 Not Found: /grapql
WARNING 2024-03-21 22:25:42,381 log 22472 1892 Not Found: /favicon.ico
ERROR 2024-03-21 22:25:50,852 log 22472 1892 Internal Server Error: /graphql
Traceback (most recent call last):
  File "c:\Users\Sergey Trosenko\DyplomaProductAggregator\.venv\Lib\site-packages\django\core\handlers\exception.py", line 55, in inner
    response = get_response(request)
               ^^^^^^^^^^^^^^^^^^^^^
  File "c:\Users\Sergey Trosenko\DyplomaProductAggregator\.venv\Lib\site-packages\django\core\handlers\base.py", line 197, in _get_response
    response = wrapped_callback(request, *callback_args, **callback_kwargs)
               ^^^^^^^^^^^^^^^^^^^^^^^^^^^^^^^^^^^^^^^^^^^^^^^^^^^^^^^^^^^^
  File "c:\Users\Sergey Trosenko\DyplomaProductAggregator\.venv\Lib\site-packages\django\views\decorators\csrf.py", line 56, in wrapper_view
    return view_func(*args, **kwargs)
           ^^^^^^^^^^^^^^^^^^^^^^^^^^
  File "c:\Users\Sergey Trosenko\DyplomaProductAggregator\.venv\Lib\site-packages\django\views\generic\base.py", line 97, in view
    self = cls(**initkwargs)
           ^^^^^^^^^^^^^^^^^
  File "c:\Users\Sergey Trosenko\DyplomaProductAggregator\.venv\Lib\site-packages\graphene_django\views.py", line 114, in __init__
    schema = graphene_settings.SCHEMA
             ^^^^^^^^^^^^^^^^^^^^^^^^
  File "c:\Users\Sergey Trosenko\DyplomaProductAggregator\.venv\Lib\site-packages\graphene_django\settings.py", line 127, in __getattr__
    val = perform_import(val, attr)
          ^^^^^^^^^^^^^^^^^^^^^^^^^
  File "c:\Users\Sergey Trosenko\DyplomaProductAggregator\.venv\Lib\site-packages\graphene_django\settings.py", line 66, in perform_import
    return import_from_string(val, setting_name)
           ^^^^^^^^^^^^^^^^^^^^^^^^^^^^^^^^^^^^^
  File "c:\Users\Sergey Trosenko\DyplomaProductAggregator\.venv\Lib\site-packages\graphene_django\settings.py", line 80, in import_from_string
    module = importlib.import_module(module_path)
             ^^^^^^^^^^^^^^^^^^^^^^^^^^^^^^^^^^^^
  File "c:\Users\Sergey Trosenko\AppData\Local\Programs\Python\Python312\Lib\importlib\__init__.py", line 90, in import_module
    return _bootstrap._gcd_import(name[level:], package, level)
           ^^^^^^^^^^^^^^^^^^^^^^^^^^^^^^^^^^^^^^^^^^^^^^^^^^^^
  File "<frozen importlib._bootstrap>", line 1381, in _gcd_import
  File "<frozen importlib._bootstrap>", line 1354, in _find_and_load
  File "<frozen importlib._bootstrap>", line 1325, in _find_and_load_unlocked
  File "<frozen importlib._bootstrap>", line 929, in _load_unlocked
  File "<frozen importlib._bootstrap_external>", line 994, in exec_module
  File "<frozen importlib._bootstrap>", line 488, in _call_with_frames_removed
  File "C:\Users\Sergey Trosenko\DyplomaProductAggregator\backend\backend\schema.py", line 4, in <module>
    import users.schema
  File "C:\Users\Sergey Trosenko\DyplomaProductAggregator\backend\users\schema.py", line 12, in <module>
    class ProfileType(DjangoObjectType):
  File "c:\Users\Sergey Trosenko\DyplomaProductAggregator\.venv\Lib\site-packages\graphene\types\objecttype.py", line 30, in __new__
    base_cls = super().__new__(
               ^^^^^^^^^^^^^^^^
  File "c:\Users\Sergey Trosenko\DyplomaProductAggregator\.venv\Lib\site-packages\graphene\utils\subclass_with_meta.py", line 46, in __init_subclass__
    super_class.__init_subclass_with_meta__(**options)
  File "c:\Users\Sergey Trosenko\DyplomaProductAggregator\.venv\Lib\site-packages\graphene_django\types.py", line 153, in __init_subclass_with_meta__
    assert is_valid_django_model(model), (
AssertionError: You need to pass a valid Django Model in ProfileType.Meta, received "None".
ERROR 2024-03-21 22:27:44,715 log 22472 1892 Internal Server Error: /graphql
Traceback (most recent call last):
  File "c:\Users\Sergey Trosenko\DyplomaProductAggregator\.venv\Lib\site-packages\django\core\handlers\exception.py", line 55, in inner
    response = get_response(request)
               ^^^^^^^^^^^^^^^^^^^^^
  File "c:\Users\Sergey Trosenko\DyplomaProductAggregator\.venv\Lib\site-packages\django\core\handlers\base.py", line 197, in _get_response
    response = wrapped_callback(request, *callback_args, **callback_kwargs)
               ^^^^^^^^^^^^^^^^^^^^^^^^^^^^^^^^^^^^^^^^^^^^^^^^^^^^^^^^^^^^
  File "c:\Users\Sergey Trosenko\DyplomaProductAggregator\.venv\Lib\site-packages\django\views\decorators\csrf.py", line 56, in wrapper_view
    return view_func(*args, **kwargs)
           ^^^^^^^^^^^^^^^^^^^^^^^^^^
  File "c:\Users\Sergey Trosenko\DyplomaProductAggregator\.venv\Lib\site-packages\django\views\generic\base.py", line 97, in view
    self = cls(**initkwargs)
           ^^^^^^^^^^^^^^^^^
  File "c:\Users\Sergey Trosenko\DyplomaProductAggregator\.venv\Lib\site-packages\graphene_django\views.py", line 114, in __init__
    schema = graphene_settings.SCHEMA
             ^^^^^^^^^^^^^^^^^^^^^^^^
  File "c:\Users\Sergey Trosenko\DyplomaProductAggregator\.venv\Lib\site-packages\graphene_django\settings.py", line 127, in __getattr__
    val = perform_import(val, attr)
          ^^^^^^^^^^^^^^^^^^^^^^^^^
  File "c:\Users\Sergey Trosenko\DyplomaProductAggregator\.venv\Lib\site-packages\graphene_django\settings.py", line 66, in perform_import
    return import_from_string(val, setting_name)
           ^^^^^^^^^^^^^^^^^^^^^^^^^^^^^^^^^^^^^
  File "c:\Users\Sergey Trosenko\DyplomaProductAggregator\.venv\Lib\site-packages\graphene_django\settings.py", line 80, in import_from_string
    module = importlib.import_module(module_path)
             ^^^^^^^^^^^^^^^^^^^^^^^^^^^^^^^^^^^^
  File "c:\Users\Sergey Trosenko\AppData\Local\Programs\Python\Python312\Lib\importlib\__init__.py", line 90, in import_module
    return _bootstrap._gcd_import(name[level:], package, level)
           ^^^^^^^^^^^^^^^^^^^^^^^^^^^^^^^^^^^^^^^^^^^^^^^^^^^^
  File "<frozen importlib._bootstrap>", line 1381, in _gcd_import
  File "<frozen importlib._bootstrap>", line 1354, in _find_and_load
  File "<frozen importlib._bootstrap>", line 1325, in _find_and_load_unlocked
  File "<frozen importlib._bootstrap>", line 929, in _load_unlocked
  File "<frozen importlib._bootstrap_external>", line 994, in exec_module
  File "<frozen importlib._bootstrap>", line 488, in _call_with_frames_removed
  File "C:\Users\Sergey Trosenko\DyplomaProductAggregator\backend\backend\schema.py", line 4, in <module>
    import users.schema
  File "C:\Users\Sergey Trosenko\DyplomaProductAggregator\backend\users\schema.py", line 12, in <module>
    class ProfileType(DjangoObjectType):
  File "c:\Users\Sergey Trosenko\DyplomaProductAggregator\.venv\Lib\site-packages\graphene\types\objecttype.py", line 30, in __new__
    base_cls = super().__new__(
               ^^^^^^^^^^^^^^^^
  File "c:\Users\Sergey Trosenko\DyplomaProductAggregator\.venv\Lib\site-packages\graphene\utils\subclass_with_meta.py", line 46, in __init_subclass__
    super_class.__init_subclass_with_meta__(**options)
  File "c:\Users\Sergey Trosenko\DyplomaProductAggregator\.venv\Lib\site-packages\graphene_django\types.py", line 153, in __init_subclass_with_meta__
    assert is_valid_django_model(model), (
AssertionError: You need to pass a valid Django Model in ProfileType.Meta, received "None".
ERROR 2024-03-21 22:28:00,416 log 22472 1892 Internal Server Error: /graphql
Traceback (most recent call last):
  File "c:\Users\Sergey Trosenko\DyplomaProductAggregator\.venv\Lib\site-packages\django\core\handlers\exception.py", line 55, in inner
    response = get_response(request)
               ^^^^^^^^^^^^^^^^^^^^^
  File "c:\Users\Sergey Trosenko\DyplomaProductAggregator\.venv\Lib\site-packages\django\core\handlers\base.py", line 197, in _get_response
    response = wrapped_callback(request, *callback_args, **callback_kwargs)
               ^^^^^^^^^^^^^^^^^^^^^^^^^^^^^^^^^^^^^^^^^^^^^^^^^^^^^^^^^^^^
  File "c:\Users\Sergey Trosenko\DyplomaProductAggregator\.venv\Lib\site-packages\django\views\decorators\csrf.py", line 56, in wrapper_view
    return view_func(*args, **kwargs)
           ^^^^^^^^^^^^^^^^^^^^^^^^^^
  File "c:\Users\Sergey Trosenko\DyplomaProductAggregator\.venv\Lib\site-packages\django\views\generic\base.py", line 97, in view
    self = cls(**initkwargs)
           ^^^^^^^^^^^^^^^^^
  File "c:\Users\Sergey Trosenko\DyplomaProductAggregator\.venv\Lib\site-packages\graphene_django\views.py", line 114, in __init__
    schema = graphene_settings.SCHEMA
             ^^^^^^^^^^^^^^^^^^^^^^^^
  File "c:\Users\Sergey Trosenko\DyplomaProductAggregator\.venv\Lib\site-packages\graphene_django\settings.py", line 127, in __getattr__
    val = perform_import(val, attr)
          ^^^^^^^^^^^^^^^^^^^^^^^^^
  File "c:\Users\Sergey Trosenko\DyplomaProductAggregator\.venv\Lib\site-packages\graphene_django\settings.py", line 66, in perform_import
    return import_from_string(val, setting_name)
           ^^^^^^^^^^^^^^^^^^^^^^^^^^^^^^^^^^^^^
  File "c:\Users\Sergey Trosenko\DyplomaProductAggregator\.venv\Lib\site-packages\graphene_django\settings.py", line 80, in import_from_string
    module = importlib.import_module(module_path)
             ^^^^^^^^^^^^^^^^^^^^^^^^^^^^^^^^^^^^
  File "c:\Users\Sergey Trosenko\AppData\Local\Programs\Python\Python312\Lib\importlib\__init__.py", line 90, in import_module
    return _bootstrap._gcd_import(name[level:], package, level)
           ^^^^^^^^^^^^^^^^^^^^^^^^^^^^^^^^^^^^^^^^^^^^^^^^^^^^
  File "<frozen importlib._bootstrap>", line 1381, in _gcd_import
  File "<frozen importlib._bootstrap>", line 1354, in _find_and_load
  File "<frozen importlib._bootstrap>", line 1325, in _find_and_load_unlocked
  File "<frozen importlib._bootstrap>", line 929, in _load_unlocked
  File "<frozen importlib._bootstrap_external>", line 994, in exec_module
  File "<frozen importlib._bootstrap>", line 488, in _call_with_frames_removed
  File "C:\Users\Sergey Trosenko\DyplomaProductAggregator\backend\backend\schema.py", line 4, in <module>
    import users.schema
  File "C:\Users\Sergey Trosenko\DyplomaProductAggregator\backend\users\schema.py", line 12, in <module>
    class ProfileType(DjangoObjectType):
  File "c:\Users\Sergey Trosenko\DyplomaProductAggregator\.venv\Lib\site-packages\graphene\types\objecttype.py", line 30, in __new__
    base_cls = super().__new__(
               ^^^^^^^^^^^^^^^^
  File "c:\Users\Sergey Trosenko\DyplomaProductAggregator\.venv\Lib\site-packages\graphene\utils\subclass_with_meta.py", line 46, in __init_subclass__
    super_class.__init_subclass_with_meta__(**options)
  File "c:\Users\Sergey Trosenko\DyplomaProductAggregator\.venv\Lib\site-packages\graphene_django\types.py", line 153, in __init_subclass_with_meta__
    assert is_valid_django_model(model), (
AssertionError: You need to pass a valid Django Model in ProfileType.Meta, received "None".
WARNING 2024-03-21 22:28:04,706 log 22472 1892 Not Found: /gtdsd
ERROR 2024-03-21 22:28:08,906 log 22472 1892 Internal Server Error: /graphql
Traceback (most recent call last):
  File "c:\Users\Sergey Trosenko\DyplomaProductAggregator\.venv\Lib\site-packages\django\core\handlers\exception.py", line 55, in inner
    response = get_response(request)
               ^^^^^^^^^^^^^^^^^^^^^
  File "c:\Users\Sergey Trosenko\DyplomaProductAggregator\.venv\Lib\site-packages\django\core\handlers\base.py", line 197, in _get_response
    response = wrapped_callback(request, *callback_args, **callback_kwargs)
               ^^^^^^^^^^^^^^^^^^^^^^^^^^^^^^^^^^^^^^^^^^^^^^^^^^^^^^^^^^^^
  File "c:\Users\Sergey Trosenko\DyplomaProductAggregator\.venv\Lib\site-packages\django\views\decorators\csrf.py", line 56, in wrapper_view
    return view_func(*args, **kwargs)
           ^^^^^^^^^^^^^^^^^^^^^^^^^^
  File "c:\Users\Sergey Trosenko\DyplomaProductAggregator\.venv\Lib\site-packages\django\views\generic\base.py", line 97, in view
    self = cls(**initkwargs)
           ^^^^^^^^^^^^^^^^^
  File "c:\Users\Sergey Trosenko\DyplomaProductAggregator\.venv\Lib\site-packages\graphene_django\views.py", line 114, in __init__
    schema = graphene_settings.SCHEMA
             ^^^^^^^^^^^^^^^^^^^^^^^^
  File "c:\Users\Sergey Trosenko\DyplomaProductAggregator\.venv\Lib\site-packages\graphene_django\settings.py", line 127, in __getattr__
    val = perform_import(val, attr)
          ^^^^^^^^^^^^^^^^^^^^^^^^^
  File "c:\Users\Sergey Trosenko\DyplomaProductAggregator\.venv\Lib\site-packages\graphene_django\settings.py", line 66, in perform_import
    return import_from_string(val, setting_name)
           ^^^^^^^^^^^^^^^^^^^^^^^^^^^^^^^^^^^^^
  File "c:\Users\Sergey Trosenko\DyplomaProductAggregator\.venv\Lib\site-packages\graphene_django\settings.py", line 80, in import_from_string
    module = importlib.import_module(module_path)
             ^^^^^^^^^^^^^^^^^^^^^^^^^^^^^^^^^^^^
  File "c:\Users\Sergey Trosenko\AppData\Local\Programs\Python\Python312\Lib\importlib\__init__.py", line 90, in import_module
    return _bootstrap._gcd_import(name[level:], package, level)
           ^^^^^^^^^^^^^^^^^^^^^^^^^^^^^^^^^^^^^^^^^^^^^^^^^^^^
  File "<frozen importlib._bootstrap>", line 1381, in _gcd_import
  File "<frozen importlib._bootstrap>", line 1354, in _find_and_load
  File "<frozen importlib._bootstrap>", line 1325, in _find_and_load_unlocked
  File "<frozen importlib._bootstrap>", line 929, in _load_unlocked
  File "<frozen importlib._bootstrap_external>", line 994, in exec_module
  File "<frozen importlib._bootstrap>", line 488, in _call_with_frames_removed
  File "C:\Users\Sergey Trosenko\DyplomaProductAggregator\backend\backend\schema.py", line 4, in <module>
    import users.schema
  File "C:\Users\Sergey Trosenko\DyplomaProductAggregator\backend\users\schema.py", line 12, in <module>
    class ProfileType(DjangoObjectType):
  File "c:\Users\Sergey Trosenko\DyplomaProductAggregator\.venv\Lib\site-packages\graphene\types\objecttype.py", line 30, in __new__
    base_cls = super().__new__(
               ^^^^^^^^^^^^^^^^
  File "c:\Users\Sergey Trosenko\DyplomaProductAggregator\.venv\Lib\site-packages\graphene\utils\subclass_with_meta.py", line 46, in __init_subclass__
    super_class.__init_subclass_with_meta__(**options)
  File "c:\Users\Sergey Trosenko\DyplomaProductAggregator\.venv\Lib\site-packages\graphene_django\types.py", line 153, in __init_subclass_with_meta__
    assert is_valid_django_model(model), (
AssertionError: You need to pass a valid Django Model in ProfileType.Meta, received "None".
ERROR 2024-03-21 22:28:21,601 log 22472 1892 Internal Server Error: /graphql
Traceback (most recent call last):
  File "c:\Users\Sergey Trosenko\DyplomaProductAggregator\.venv\Lib\site-packages\django\core\handlers\exception.py", line 55, in inner
    response = get_response(request)
               ^^^^^^^^^^^^^^^^^^^^^
  File "c:\Users\Sergey Trosenko\DyplomaProductAggregator\.venv\Lib\site-packages\django\core\handlers\base.py", line 197, in _get_response
    response = wrapped_callback(request, *callback_args, **callback_kwargs)
               ^^^^^^^^^^^^^^^^^^^^^^^^^^^^^^^^^^^^^^^^^^^^^^^^^^^^^^^^^^^^
  File "c:\Users\Sergey Trosenko\DyplomaProductAggregator\.venv\Lib\site-packages\django\views\decorators\csrf.py", line 56, in wrapper_view
    return view_func(*args, **kwargs)
           ^^^^^^^^^^^^^^^^^^^^^^^^^^
  File "c:\Users\Sergey Trosenko\DyplomaProductAggregator\.venv\Lib\site-packages\django\views\generic\base.py", line 97, in view
    self = cls(**initkwargs)
           ^^^^^^^^^^^^^^^^^
  File "c:\Users\Sergey Trosenko\DyplomaProductAggregator\.venv\Lib\site-packages\graphene_django\views.py", line 114, in __init__
    schema = graphene_settings.SCHEMA
             ^^^^^^^^^^^^^^^^^^^^^^^^
  File "c:\Users\Sergey Trosenko\DyplomaProductAggregator\.venv\Lib\site-packages\graphene_django\settings.py", line 127, in __getattr__
    val = perform_import(val, attr)
          ^^^^^^^^^^^^^^^^^^^^^^^^^
  File "c:\Users\Sergey Trosenko\DyplomaProductAggregator\.venv\Lib\site-packages\graphene_django\settings.py", line 66, in perform_import
    return import_from_string(val, setting_name)
           ^^^^^^^^^^^^^^^^^^^^^^^^^^^^^^^^^^^^^
  File "c:\Users\Sergey Trosenko\DyplomaProductAggregator\.venv\Lib\site-packages\graphene_django\settings.py", line 80, in import_from_string
    module = importlib.import_module(module_path)
             ^^^^^^^^^^^^^^^^^^^^^^^^^^^^^^^^^^^^
  File "c:\Users\Sergey Trosenko\AppData\Local\Programs\Python\Python312\Lib\importlib\__init__.py", line 90, in import_module
    return _bootstrap._gcd_import(name[level:], package, level)
           ^^^^^^^^^^^^^^^^^^^^^^^^^^^^^^^^^^^^^^^^^^^^^^^^^^^^
  File "<frozen importlib._bootstrap>", line 1381, in _gcd_import
  File "<frozen importlib._bootstrap>", line 1354, in _find_and_load
  File "<frozen importlib._bootstrap>", line 1325, in _find_and_load_unlocked
  File "<frozen importlib._bootstrap>", line 929, in _load_unlocked
  File "<frozen importlib._bootstrap_external>", line 994, in exec_module
  File "<frozen importlib._bootstrap>", line 488, in _call_with_frames_removed
  File "C:\Users\Sergey Trosenko\DyplomaProductAggregator\backend\backend\schema.py", line 4, in <module>
    import users.schema
  File "C:\Users\Sergey Trosenko\DyplomaProductAggregator\backend\users\schema.py", line 9, in <module>
    from profiles.models import Profile
  File "C:\Users\Sergey Trosenko\DyplomaProductAggregator\backend\profiles\models.py", line 5, in <module>
    class Profile(models.Model):
  File "c:\Users\Sergey Trosenko\DyplomaProductAggregator\.venv\Lib\site-packages\django\db\models\base.py", line 134, in __new__
    raise RuntimeError(
RuntimeError: Model class profiles.models.Profile doesn't declare an explicit app_label and isn't in an application in INSTALLED_APPS.
ERROR 2024-03-21 22:29:14,015 log 22472 1892 Internal Server Error: /graphql
Traceback (most recent call last):
  File "c:\Users\Sergey Trosenko\DyplomaProductAggregator\.venv\Lib\site-packages\django\core\handlers\exception.py", line 55, in inner
    response = get_response(request)
               ^^^^^^^^^^^^^^^^^^^^^
  File "c:\Users\Sergey Trosenko\DyplomaProductAggregator\.venv\Lib\site-packages\django\core\handlers\base.py", line 197, in _get_response
    response = wrapped_callback(request, *callback_args, **callback_kwargs)
               ^^^^^^^^^^^^^^^^^^^^^^^^^^^^^^^^^^^^^^^^^^^^^^^^^^^^^^^^^^^^
  File "c:\Users\Sergey Trosenko\DyplomaProductAggregator\.venv\Lib\site-packages\django\views\decorators\csrf.py", line 56, in wrapper_view
    return view_func(*args, **kwargs)
           ^^^^^^^^^^^^^^^^^^^^^^^^^^
  File "c:\Users\Sergey Trosenko\DyplomaProductAggregator\.venv\Lib\site-packages\django\views\generic\base.py", line 97, in view
    self = cls(**initkwargs)
           ^^^^^^^^^^^^^^^^^
  File "c:\Users\Sergey Trosenko\DyplomaProductAggregator\.venv\Lib\site-packages\graphene_django\views.py", line 114, in __init__
    schema = graphene_settings.SCHEMA
             ^^^^^^^^^^^^^^^^^^^^^^^^
  File "c:\Users\Sergey Trosenko\DyplomaProductAggregator\.venv\Lib\site-packages\graphene_django\settings.py", line 127, in __getattr__
    val = perform_import(val, attr)
          ^^^^^^^^^^^^^^^^^^^^^^^^^
  File "c:\Users\Sergey Trosenko\DyplomaProductAggregator\.venv\Lib\site-packages\graphene_django\settings.py", line 66, in perform_import
    return import_from_string(val, setting_name)
           ^^^^^^^^^^^^^^^^^^^^^^^^^^^^^^^^^^^^^
  File "c:\Users\Sergey Trosenko\DyplomaProductAggregator\.venv\Lib\site-packages\graphene_django\settings.py", line 80, in import_from_string
    module = importlib.import_module(module_path)
             ^^^^^^^^^^^^^^^^^^^^^^^^^^^^^^^^^^^^
  File "c:\Users\Sergey Trosenko\AppData\Local\Programs\Python\Python312\Lib\importlib\__init__.py", line 90, in import_module
    return _bootstrap._gcd_import(name[level:], package, level)
           ^^^^^^^^^^^^^^^^^^^^^^^^^^^^^^^^^^^^^^^^^^^^^^^^^^^^
  File "<frozen importlib._bootstrap>", line 1381, in _gcd_import
  File "<frozen importlib._bootstrap>", line 1354, in _find_and_load
  File "<frozen importlib._bootstrap>", line 1325, in _find_and_load_unlocked
  File "<frozen importlib._bootstrap>", line 929, in _load_unlocked
  File "<frozen importlib._bootstrap_external>", line 994, in exec_module
  File "<frozen importlib._bootstrap>", line 488, in _call_with_frames_removed
  File "C:\Users\Sergey Trosenko\DyplomaProductAggregator\backend\backend\schema.py", line 4, in <module>
    import users.schema
  File "C:\Users\Sergey Trosenko\DyplomaProductAggregator\backend\users\schema.py", line 9, in <module>
    from profiles.models import Profile
  File "C:\Users\Sergey Trosenko\DyplomaProductAggregator\backend\profiles\models.py", line 5, in <module>
    class Profile(models.Model):
  File "c:\Users\Sergey Trosenko\DyplomaProductAggregator\.venv\Lib\site-packages\django\db\models\base.py", line 134, in __new__
    raise RuntimeError(
RuntimeError: Model class profiles.models.Profile doesn't declare an explicit app_label and isn't in an application in INSTALLED_APPS.
ERROR 2024-03-21 22:29:21,972 log 23128 9108 Internal Server Error: /graphql
Traceback (most recent call last):
  File "c:\Users\Sergey Trosenko\DyplomaProductAggregator\.venv\Lib\site-packages\django\core\handlers\exception.py", line 55, in inner
    response = get_response(request)
               ^^^^^^^^^^^^^^^^^^^^^
  File "c:\Users\Sergey Trosenko\DyplomaProductAggregator\.venv\Lib\site-packages\django\core\handlers\base.py", line 197, in _get_response
    response = wrapped_callback(request, *callback_args, **callback_kwargs)
               ^^^^^^^^^^^^^^^^^^^^^^^^^^^^^^^^^^^^^^^^^^^^^^^^^^^^^^^^^^^^
  File "c:\Users\Sergey Trosenko\DyplomaProductAggregator\.venv\Lib\site-packages\django\views\decorators\csrf.py", line 56, in wrapper_view
    return view_func(*args, **kwargs)
           ^^^^^^^^^^^^^^^^^^^^^^^^^^
  File "c:\Users\Sergey Trosenko\DyplomaProductAggregator\.venv\Lib\site-packages\django\views\generic\base.py", line 97, in view
    self = cls(**initkwargs)
           ^^^^^^^^^^^^^^^^^
  File "c:\Users\Sergey Trosenko\DyplomaProductAggregator\.venv\Lib\site-packages\graphene_django\views.py", line 114, in __init__
    schema = graphene_settings.SCHEMA
             ^^^^^^^^^^^^^^^^^^^^^^^^
  File "c:\Users\Sergey Trosenko\DyplomaProductAggregator\.venv\Lib\site-packages\graphene_django\settings.py", line 127, in __getattr__
    val = perform_import(val, attr)
          ^^^^^^^^^^^^^^^^^^^^^^^^^
  File "c:\Users\Sergey Trosenko\DyplomaProductAggregator\.venv\Lib\site-packages\graphene_django\settings.py", line 66, in perform_import
    return import_from_string(val, setting_name)
           ^^^^^^^^^^^^^^^^^^^^^^^^^^^^^^^^^^^^^
  File "c:\Users\Sergey Trosenko\DyplomaProductAggregator\.venv\Lib\site-packages\graphene_django\settings.py", line 80, in import_from_string
    module = importlib.import_module(module_path)
             ^^^^^^^^^^^^^^^^^^^^^^^^^^^^^^^^^^^^
  File "c:\Users\Sergey Trosenko\AppData\Local\Programs\Python\Python312\Lib\importlib\__init__.py", line 90, in import_module
    return _bootstrap._gcd_import(name[level:], package, level)
           ^^^^^^^^^^^^^^^^^^^^^^^^^^^^^^^^^^^^^^^^^^^^^^^^^^^^
  File "<frozen importlib._bootstrap>", line 1381, in _gcd_import
  File "<frozen importlib._bootstrap>", line 1354, in _find_and_load
  File "<frozen importlib._bootstrap>", line 1325, in _find_and_load_unlocked
  File "<frozen importlib._bootstrap>", line 929, in _load_unlocked
  File "<frozen importlib._bootstrap_external>", line 994, in exec_module
  File "<frozen importlib._bootstrap>", line 488, in _call_with_frames_removed
  File "C:\Users\Sergey Trosenko\DyplomaProductAggregator\backend\backend\schema.py", line 4, in <module>
    import users.schema
  File "C:\Users\Sergey Trosenko\DyplomaProductAggregator\backend\users\schema.py", line 9, in <module>
    from profiles.models import Profile
  File "C:\Users\Sergey Trosenko\DyplomaProductAggregator\backend\profiles\models.py", line 5, in <module>
    class Profile(models.Model):
  File "c:\Users\Sergey Trosenko\DyplomaProductAggregator\.venv\Lib\site-packages\django\db\models\base.py", line 134, in __new__
    raise RuntimeError(
RuntimeError: Model class profiles.models.Profile doesn't declare an explicit app_label and isn't in an application in INSTALLED_APPS.
WARNING 2024-03-24 14:51:42,422 log 19208 3892 Not Found: /api/v1/users/
WARNING 2024-03-24 14:51:57,718 log 19208 1152 Not Found: /favicon.ico
WARNING 2024-03-24 14:56:57,834 log 19208 22768 Not Found: /api/v1/users/
WARNING 2024-03-24 14:58:04,619 log 19208 22448 Not Found: /users
WARNING 2024-03-24 15:04:21,951 log 19208 22768 Not Found: /api/v1/users/
WARNING 2024-03-24 15:04:28,726 log 19208 16884 Not Found: /media/
WARNING 2024-03-24 15:04:52,833 log 19208 8876 Not Found: /media/
WARNING 2024-03-24 15:05:08,822 log 19208 5332 Not Found: /media/
WARNING 2024-03-24 17:41:18,171 log 19208 15732 Not Found: /media/
WARNING 2024-03-24 17:42:39,805 log 19208 20316 Not Found: /media/
WARNING 2024-03-24 17:48:22,576 log 19208 24988 Not Found: /media/
WARNING 2024-03-24 17:48:56,546 log 19208 14476 Bad Request: /graphql
WARNING 2024-03-24 17:49:17,820 log 19208 14476 Bad Request: /graphql
WARNING 2024-03-24 17:50:14,542 log 19208 19384 Not Found: /media/
WARNING 2024-03-24 17:51:51,053 log 19208 5428 Not Found: /media/
WARNING 2024-03-24 17:52:06,866 log 19208 16160 Bad Request: /graphql
WARNING 2024-03-24 17:52:20,697 log 19208 16160 Bad Request: /graphql
WARNING 2024-03-24 17:58:43,621 log 4904 1696 Not Found: /api/v1/users/
WARNING 2024-03-24 18:00:08,742 log 4904 1696 Not Found: /api/v1/users/
WARNING 2024-03-25 18:19:41,378 log 14048 19820 Not Found: /favicon.ico
WARNING 2024-03-25 20:20:30,495 log 5436 2144 Not Found: /media/
WARNING 2024-03-25 20:21:30,715 log 5436 2388 Not Found: /media/
WARNING 2024-03-25 20:22:33,149 log 5436 13300 Not Found: /media/
WARNING 2024-03-25 20:22:48,770 log 5436 20544 Not Found: /media/
WARNING 2024-03-25 20:22:56,354 log 5436 21368 Not Found: /media/
WARNING 2024-03-25 20:27:25,944 log 5436 11844 Not Found: /media/
WARNING 2024-03-25 20:29:00,240 log 5436 5796 Not Found: /media/
WARNING 2024-03-25 20:29:56,255 log 5436 8288 Not Found: /media/
WARNING 2024-03-25 20:29:58,215 log 5436 19160 Not Found: /media/
WARNING 2024-03-25 20:33:57,588 log 3872 9104 Not Found: /media/
WARNING 2024-03-25 20:34:13,491 log 3872 12872 Bad Request: /graphql
WARNING 2024-03-25 20:35:26,403 log 3872 10368 Not Found: /media/
WARNING 2024-03-25 20:35:33,678 log 3872 12872 Bad Request: /graphql
WARNING 2024-03-25 20:35:50,682 log 3872 7140 Not Found: /media/
WARNING 2024-03-25 20:36:02,006 log 3872 12872 Bad Request: /graphql
WARNING 2024-03-25 20:36:33,912 log 7500 14012 Not Found: /media/
WARNING 2024-03-25 20:36:39,061 log 7500 1744 Bad Request: /graphql
WARNING 2024-03-25 20:38:59,988 log 7500 1744 Bad Request: /graphql
WARNING 2024-03-25 20:39:00,423 log 7500 12868 Not Found: /media/
WARNING 2024-03-25 20:39:03,310 log 7500 1744 Bad Request: /graphql
WARNING 2024-03-25 20:39:03,391 log 7500 1424 Not Found: /media/
WARNING 2024-03-25 20:39:14,872 log 7500 1744 Bad Request: /graphql
WARNING 2024-03-25 20:39:40,664 log 7500 1744 Bad Request: /graphql
WARNING 2024-03-25 20:39:41,089 log 7500 6440 Not Found: /media/
WARNING 2024-03-25 20:40:14,764 log 7500 1744 Bad Request: /graphql
WARNING 2024-03-25 20:40:14,804 log 7500 13768 Not Found: /media/
WARNING 2024-03-25 20:40:17,466 log 7500 1744 Bad Request: /graphql
WARNING 2024-03-25 20:40:17,850 log 7500 14236 Not Found: /media/
WARNING 2024-03-25 20:40:31,834 log 7500 1744 Bad Request: /graphql
WARNING 2024-03-25 20:42:30,829 log 7500 1744 Bad Request: /graphql
WARNING 2024-03-25 20:42:31,243 log 7500 19788 Not Found: /media/
WARNING 2024-03-25 20:42:38,733 log 7500 1744 Bad Request: /graphql
WARNING 2024-03-25 20:43:51,231 log 7500 21188 Bad Request: /graphql
WARNING 2024-03-25 20:43:51,283 log 7500 20800 Not Found: /media/
WARNING 2024-03-25 20:43:52,365 log 7500 21188 Bad Request: /graphql
WARNING 2024-03-25 20:43:52,477 log 7500 740 Not Found: /media/
WARNING 2024-03-25 20:44:06,101 log 7500 8544 Bad Request: /graphql
WARNING 2024-03-25 20:44:06,104 log 7500 20284 Bad Request: /graphql
WARNING 2024-03-25 20:44:15,427 log 7500 17048 Bad Request: /graphql
WARNING 2024-03-25 20:44:15,530 log 7500 8524 Not Found: /media/
WARNING 2024-03-25 20:44:20,112 log 7500 17048 Bad Request: /graphql
WARNING 2024-03-25 20:44:48,873 log 7500 17048 Bad Request: /graphql
WARNING 2024-03-25 20:44:48,973 log 7500 20720 Not Found: /media/
WARNING 2024-03-25 20:44:50,847 log 7500 17048 Bad Request: /graphql
WARNING 2024-03-25 20:44:51,183 log 7500 8516 Not Found: /media/
WARNING 2024-03-25 20:44:52,528 log 7500 17048 Bad Request: /graphql
WARNING 2024-03-25 20:44:52,607 log 7500 6120 Not Found: /media/
WARNING 2024-03-25 20:44:58,001 log 7500 17048 Bad Request: /graphql
WARNING 2024-03-25 20:45:13,401 log 7500 18344 Not Found: /media/
WARNING 2024-03-25 20:45:19,589 log 7500 964 Bad Request: /graphql
WARNING 2024-03-25 20:46:48,014 log 7500 20824 Not Found: /media/
WARNING 2024-03-25 20:46:50,121 log 7500 9448 Not Found: /media/
WARNING 2024-03-25 20:46:54,850 log 7500 19048 Not Found: /media/
WARNING 2024-03-25 20:47:02,996 log 7500 9580 Bad Request: /graphql
WARNING 2024-03-25 20:49:57,732 log 2180 4832 Not Found: /media/
WARNING 2024-03-25 20:50:01,583 log 2180 9728 Bad Request: /graphql
WARNING 2024-03-25 20:50:56,576 log 2180 6412 Not Found: /media/
WARNING 2024-03-25 20:51:00,954 log 2180 9728 Bad Request: /graphql
WARNING 2024-03-25 20:51:22,788 log 20872 1008 Not Found: /media/
WARNING 2024-03-25 20:51:23,868 log 20872 16276 Bad Request: /graphql
WARNING 2024-03-25 20:52:24,739 log 20872 16276 Bad Request: /graphql
WARNING 2024-03-25 20:52:25,153 log 20872 1308 Not Found: /media/
WARNING 2024-03-25 20:52:26,213 log 20872 16276 Bad Request: /graphql
WARNING 2024-03-25 20:52:26,296 log 20872 10936 Not Found: /media/
WARNING 2024-03-25 20:52:31,242 log 20872 16276 Bad Request: /graphql
WARNING 2024-03-25 20:53:27,165 log 20872 16276 Bad Request: /graphql
WARNING 2024-03-25 20:53:27,564 log 20872 4144 Not Found: /media/
WARNING 2024-03-25 20:53:37,143 log 20872 16276 Bad Request: /graphql
WARNING 2024-03-25 20:53:41,697 log 20872 16276 Bad Request: /graphql
WARNING 2024-03-25 20:53:44,302 log 20872 16276 Bad Request: /graphql
WARNING 2024-03-25 20:53:44,405 log 20872 19524 Not Found: /media/
WARNING 2024-03-25 20:53:58,412 log 20872 16276 Bad Request: /graphql
WARNING 2024-03-25 21:28:52,499 log 6544 9424 Not Found: /media/
WARNING 2024-03-25 21:29:04,771 log 6544 14236 Bad Request: /graphql
WARNING 2024-03-25 21:30:11,687 log 6544 21332 Not Found: /media/
WARNING 2024-03-25 21:30:16,348 log 6544 23092 Bad Request: /graphql
WARNING 2024-03-25 21:31:10,276 log 6544 9812 Not Found: /media/
WARNING 2024-03-25 21:31:32,366 log 6544 16568 Not Found: /media/
WARNING 2024-03-25 21:31:37,410 log 6544 22524 Not Found: /media/
WARNING 2024-03-25 21:31:45,224 log 6544 23092 Bad Request: /graphql
WARNING 2024-03-25 21:32:47,823 log 17748 3292 Not Found: /media/
WARNING 2024-03-25 21:33:19,946 log 17628 20828 Not Found: /media/
WARNING 2024-03-25 21:33:25,185 log 17628 1308 Bad Request: /graphql
WARNING 2024-03-25 21:35:25,658 log 17628 22032 Not Found: /media/
WARNING 2024-03-25 21:35:26,752 log 17628 3020 Not Found: /media/
WARNING 2024-03-25 21:35:32,346 log 17628 1308 Bad Request: /graphql
WARNING 2024-03-25 21:37:50,392 log 8328 20260 Not Found: /media/
WARNING 2024-03-25 21:37:54,214 log 8328 20580 Bad Request: /graphql
WARNING 2024-03-25 21:38:26,047 log 8328 13620 Not Found: /media/
WARNING 2024-03-25 21:38:28,651 log 8328 9360 Not Found: /media/
WARNING 2024-03-25 21:38:33,217 log 8328 20580 Bad Request: /graphql
WARNING 2024-03-25 21:38:59,921 log 19968 11836 Not Found: /media/
WARNING 2024-03-25 21:39:01,199 log 19968 17744 Bad Request: /graphql
WARNING 2024-03-25 21:39:03,264 log 19968 21996 Not Found: /media/
WARNING 2024-03-25 21:39:08,501 log 19968 17744 Bad Request: /graphql
WARNING 2024-03-25 21:40:28,066 log 19968 22128 Not Found: /media/
WARNING 2024-03-25 21:40:31,354 log 19968 17744 Bad Request: /graphql
WARNING 2024-03-25 21:41:17,797 log 19968 7200 Not Found: /media/
WARNING 2024-03-25 21:41:19,484 log 19968 21104 Not Found: /media/
WARNING 2024-03-25 21:41:24,249 log 19968 17744 Bad Request: /graphql
WARNING 2024-03-25 21:42:04,359 log 19968 6060 Not Found: /media/
WARNING 2024-03-25 21:42:08,167 log 19968 17744 Bad Request: /graphql
WARNING 2024-03-25 21:42:19,981 log 19968 23076 Not Found: /media/
WARNING 2024-03-25 21:42:21,141 log 19968 17744 Bad Request: /graphql
WARNING 2024-03-25 21:42:27,723 log 2924 14524 Not Found: /media/
WARNING 2024-03-25 21:42:58,363 log 16432 7308 Not Found: /media/
WARNING 2024-03-25 21:44:43,003 log 16432 2196 Not Found: /favicon.ico
WARNING 2024-03-25 21:45:13,004 log 16432 5084 Bad Request: /graphql
WARNING 2024-03-25 21:45:13,124 log 16432 2196 Not Found: /media/
WARNING 2024-03-25 21:45:14,623 log 16432 5084 Bad Request: /graphql
WARNING 2024-03-25 21:45:14,699 log 16432 11364 Not Found: /media/
WARNING 2024-03-25 21:45:19,872 log 16432 5084 Bad Request: /graphql
WARNING 2024-03-25 21:47:04,913 log 16432 5084 Bad Request: /graphql
WARNING 2024-03-25 21:47:05,268 log 16432 22992 Not Found: /media/
WARNING 2024-03-25 21:47:07,044 log 16432 5084 Bad Request: /graphql
WARNING 2024-03-25 21:47:07,125 log 16432 8468 Not Found: /media/
WARNING 2024-03-25 21:47:15,651 log 16432 5084 Bad Request: /graphql
WARNING 2024-03-25 21:47:41,306 log 16432 5084 Bad Request: /graphql
WARNING 2024-03-25 21:47:41,719 log 16432 2940 Not Found: /media/
WARNING 2024-03-25 21:47:43,683 log 16432 5084 Bad Request: /graphql
WARNING 2024-03-25 21:47:43,766 log 16432 13300 Not Found: /media/
WARNING 2024-03-25 21:48:07,447 log 16432 5084 Bad Request: /graphql
WARNING 2024-03-25 21:48:07,848 log 16432 23356 Not Found: /media/
WARNING 2024-03-25 21:48:16,685 log 16432 5084 Bad Request: /graphql
WARNING 2024-03-25 21:48:37,114 log 16432 5084 Bad Request: /graphql
WARNING 2024-03-25 21:48:37,196 log 16432 16088 Not Found: /media/
WARNING 2024-03-25 21:48:49,072 log 16432 5084 Bad Request: /graphql
WARNING 2024-03-25 21:48:49,167 log 16432 19844 Not Found: /media/
WARNING 2024-03-25 21:49:59,220 log 16432 5084 Bad Request: /graphql
WARNING 2024-03-25 21:49:59,572 log 16432 4484 Not Found: /media/
WARNING 2024-03-25 21:50:01,670 log 16432 5084 Bad Request: /graphql
WARNING 2024-03-25 21:50:01,768 log 16432 23072 Not Found: /media/
WARNING 2024-03-25 21:50:17,985 log 16432 5084 Bad Request: /graphql
WARNING 2024-03-25 21:50:33,485 log 16432 5084 Bad Request: /graphql
WARNING 2024-03-25 21:50:33,902 log 16432 8552 Not Found: /media/
WARNING 2024-03-25 21:51:55,853 log 16432 5084 Bad Request: /graphql
WARNING 2024-03-25 21:51:56,301 log 16432 22668 Not Found: /media/
WARNING 2024-03-25 21:52:16,762 log 16432 5084 Bad Request: /graphql
WARNING 2024-03-25 21:52:16,875 log 16432 10556 Not Found: /media/
WARNING 2024-03-25 21:52:18,953 log 16432 5084 Bad Request: /graphql
WARNING 2024-03-25 21:52:19,307 log 16432 20892 Not Found: /media/
WARNING 2024-03-25 21:52:21,718 log 16432 5084 Bad Request: /graphql
WARNING 2024-03-25 21:52:21,826 log 16432 6452 Not Found: /media/
WARNING 2024-03-25 21:52:32,909 log 16432 5084 Bad Request: /graphql
WARNING 2024-03-25 21:53:00,257 log 16432 5084 Bad Request: /graphql
WARNING 2024-03-25 21:53:00,619 log 16432 6356 Not Found: /media/
WARNING 2024-03-25 21:53:02,172 log 16432 5084 Bad Request: /graphql
WARNING 2024-03-25 21:53:02,281 log 16432 15216 Not Found: /media/
WARNING 2024-03-25 21:53:14,509 log 16432 5084 Bad Request: /graphql
WARNING 2024-03-25 21:53:42,832 log 16432 5084 Bad Request: /graphql
WARNING 2024-03-25 21:53:43,183 log 16432 3736 Not Found: /media/
WARNING 2024-03-25 21:53:45,913 log 16432 5084 Bad Request: /graphql
WARNING 2024-03-25 21:53:46,010 log 16432 21272 Not Found: /media/
WARNING 2024-03-25 21:53:49,751 log 16432 5084 Bad Request: /graphql
WARNING 2024-03-25 21:54:39,380 log 16432 5084 Bad Request: /graphql
WARNING 2024-03-25 21:54:39,812 log 16432 8132 Not Found: /media/
WARNING 2024-03-25 21:54:50,173 log 16432 5084 Bad Request: /graphql
WARNING 2024-03-25 21:55:16,563 log 16432 5084 Bad Request: /graphql
WARNING 2024-03-25 21:55:16,665 log 16432 1364 Not Found: /media/
WARNING 2024-03-25 21:55:29,758 log 16432 5084 Bad Request: /graphql
WARNING 2024-03-25 21:55:30,147 log 16432 9820 Not Found: /media/
WARNING 2024-03-25 21:55:46,029 log 16432 5084 Bad Request: /graphql
WARNING 2024-03-25 21:55:46,117 log 16432 21104 Not Found: /media/
WARNING 2024-03-25 21:55:53,386 log 16432 5084 Bad Request: /graphql
WARNING 2024-03-25 21:56:16,765 log 16432 5084 Bad Request: /graphql
WARNING 2024-03-25 21:56:17,155 log 16432 8528 Not Found: /media/
WARNING 2024-03-25 21:56:35,403 log 16432 5084 Bad Request: /graphql
WARNING 2024-03-25 21:56:35,443 log 16432 8544 Not Found: /media/
WARNING 2024-03-25 21:56:37,815 log 16432 5084 Bad Request: /graphql
WARNING 2024-03-25 21:56:38,220 log 16432 22032 Not Found: /media/
WARNING 2024-03-25 21:56:50,650 log 16432 5084 Bad Request: /graphql
WARNING 2024-03-25 21:57:34,627 log 16432 21800 Not Found: /media/
WARNING 2024-03-25 21:57:35,960 log 16432 11392 Not Found: /media/
WARNING 2024-03-25 21:58:12,379 log 16432 22412 Not Found: /media/
WARNING 2024-03-25 21:58:15,751 log 16432 21732 Not Found: /media/
WARNING 2024-03-25 21:58:27,835 log 16432 8528 Not Found: /favicon.ico
WARNING 2024-03-25 22:26:43,895 log 16432 16164 Not Found: /media/
WARNING 2024-03-25 22:27:44,918 log 16432 21560 Not Found: /media/
WARNING 2024-03-25 22:30:47,410 log 23572 1396 Not Found: /media/
WARNING 2024-03-25 22:31:44,621 log 23756 19204 Not Found: /media/
WARNING 2024-03-25 22:31:56,749 log 23756 10140 Not Found: /media/
WARNING 2024-03-25 22:32:53,962 log 23756 1876 Not Found: /media/
WARNING 2024-03-25 22:35:46,803 log 23756 13528 Not Found: /media/
WARNING 2024-03-25 22:36:39,009 log 23756 13236 Not Found: /media/
WARNING 2024-03-25 22:41:11,898 log 23756 18404 Not Found: /media/
WARNING 2024-03-25 22:43:43,250 log 23756 7628 Not Found: /media/
WARNING 2024-03-25 22:43:45,654 log 23756 14364 Not Found: /media/
WARNING 2024-03-25 22:45:40,120 log 14284 14628 Not Found: /media/
WARNING 2024-03-25 22:45:42,965 log 14284 21812 Not Found: /media/
WARNING 2024-03-25 22:46:32,435 log 14284 3680 Not Found: /media/
WARNING 2024-03-25 22:47:33,681 log 22952 21432 Not Found: /media/
WARNING 2024-03-25 22:47:59,303 log 22952 13812 Not Found: /media/
WARNING 2024-03-25 22:48:21,487 log 22952 10180 Not Found: /media/
WARNING 2024-03-25 22:48:35,740 log 22952 17916 Not Found: /media/
WARNING 2024-03-25 22:49:00,335 log 20776 21916 Not Found: /media/
WARNING 2024-03-25 22:49:08,906 log 20776 17424 Not Found: /media/
WARNING 2024-03-25 22:49:29,237 log 16816 16828 Not Found: /media/
WARNING 2024-03-25 22:49:29,366 log 16816 21332 Bad Request: /graphql
WARNING 2024-03-25 22:49:50,046 log 16816 21332 Bad Request: /graphql
WARNING 2024-03-25 22:49:53,880 log 16816 21332 Bad Request: /graphql
WARNING 2024-03-25 22:49:53,919 log 16816 10328 Not Found: /media/
WARNING 2024-03-25 22:50:14,072 log 16816 21332 Bad Request: /graphql
WARNING 2024-03-25 22:50:14,473 log 16816 23736 Not Found: /media/
WARNING 2024-03-25 22:50:33,237 log 16816 21332 Bad Request: /graphql
WARNING 2024-03-25 22:50:33,324 log 16816 24436 Not Found: /media/
WARNING 2024-03-25 22:50:35,979 log 16816 21332 Bad Request: /graphql
WARNING 2024-03-25 22:50:36,385 log 16816 23276 Not Found: /media/
WARNING 2024-03-25 22:50:38,604 log 16816 21332 Bad Request: /graphql
WARNING 2024-03-25 22:50:38,686 log 16816 3364 Not Found: /media/
WARNING 2024-03-25 22:51:05,830 log 16816 21332 Bad Request: /graphql
WARNING 2024-03-25 22:51:08,444 log 16816 21332 Bad Request: /graphql
WARNING 2024-03-25 22:51:08,808 log 16816 22696 Not Found: /media/
WARNING 2024-03-25 22:51:12,821 log 16816 21332 Bad Request: /graphql
WARNING 2024-03-25 22:51:12,907 log 16816 18760 Not Found: /media/
WARNING 2024-03-25 22:51:31,134 log 11624 21632 Not Found: /media/
WARNING 2024-03-25 22:51:32,079 log 11624 13584 Not Found: /media/
WARNING 2024-03-25 22:54:34,199 log 22868 23872 Not Found: /media/
WARNING 2024-03-25 22:54:41,005 log 22868 23992 Bad Request: /graphql
WARNING 2024-03-25 22:55:06,116 log 16244 13236 Bad Request: /graphql
WARNING 2024-03-25 22:55:06,125 log 16244 6544 Not Found: /media/
WARNING 2024-03-25 22:55:10,556 log 16244 13236 Bad Request: /graphql
WARNING 2024-03-25 22:55:51,470 log 16244 13236 Bad Request: /graphql
WARNING 2024-03-25 22:55:51,522 log 16244 6288 Not Found: /media/
WARNING 2024-03-25 22:55:52,942 log 16244 13236 Bad Request: /graphql
WARNING 2024-03-25 22:55:53,340 log 16244 18596 Not Found: /media/
WARNING 2024-03-25 22:56:03,285 log 16244 13236 Bad Request: /graphql
WARNING 2024-03-25 22:56:20,646 log 22084 14068 Not Found: /media/
WARNING 2024-03-25 22:56:23,618 log 22084 11188 Bad Request: /graphql
WARNING 2024-03-25 22:56:34,179 log 21984 7884 Bad Request: /graphql
WARNING 2024-03-25 22:56:34,185 log 21984 12196 Not Found: /media/
WARNING 2024-03-25 22:56:37,057 log 21984 7884 Bad Request: /graphql
WARNING 2024-03-25 22:57:00,347 log 21984 7884 Bad Request: /graphql
WARNING 2024-03-25 22:57:00,382 log 21984 22212 Not Found: /media/
WARNING 2024-03-25 22:57:01,635 log 21984 7884 Bad Request: /graphql
WARNING 2024-03-25 22:57:02,034 log 21984 23904 Not Found: /media/
WARNING 2024-03-25 22:57:05,299 log 21984 7884 Bad Request: /graphql
WARNING 2024-03-26 12:03:59,602 log 21984 21644 Bad Request: /graphql
WARNING 2024-03-26 12:03:59,676 log 21984 13244 Not Found: /media/
WARNING 2024-03-26 12:06:27,283 log 21984 24104 Bad Request: /graphql
WARNING 2024-03-26 12:06:27,334 log 21984 8200 Not Found: /media/
WARNING 2024-03-26 12:06:42,216 log 21984 24104 Bad Request: /graphql
WARNING 2024-03-26 12:07:23,628 log 23768 9056 Bad Request: /graphql
WARNING 2024-03-26 12:07:23,632 log 23768 22600 Not Found: /media/
WARNING 2024-03-26 12:07:28,199 log 23768 9056 Bad Request: /graphql
WARNING 2024-03-26 12:07:40,997 log 23768 9056 Bad Request: /graphql
WARNING 2024-03-26 12:07:44,919 log 23768 9056 Bad Request: /graphql
WARNING 2024-03-26 12:07:45,005 log 23768 24184 Not Found: /media/
WARNING 2024-03-26 12:09:24,617 log 23768 9056 Bad Request: /graphql
WARNING 2024-03-26 12:09:25,045 log 23768 20244 Not Found: /media/
WARNING 2024-03-26 12:11:57,849 log 23768 9056 Bad Request: /graphql
WARNING 2024-03-26 12:11:58,205 log 23768 13088 Not Found: /media/
WARNING 2024-03-26 12:11:59,083 log 23768 9056 Bad Request: /graphql
WARNING 2024-03-26 12:11:59,176 log 23768 3596 Not Found: /media/
WARNING 2024-03-26 12:12:33,722 log 23768 9056 Bad Request: /graphql
WARNING 2024-03-26 12:12:34,112 log 23768 8828 Not Found: /media/
WARNING 2024-03-26 12:14:49,717 log 23768 9056 Bad Request: /graphql
WARNING 2024-03-26 12:14:50,132 log 23768 3976 Not Found: /media/
WARNING 2024-03-26 12:18:01,698 log 23768 9056 Bad Request: /graphql
WARNING 2024-03-26 12:18:02,124 log 23768 3344 Not Found: /media/
WARNING 2024-03-26 12:18:04,529 log 23768 9056 Bad Request: /graphql
WARNING 2024-03-26 12:18:04,605 log 23768 22840 Not Found: /media/
WARNING 2024-03-26 12:18:16,802 log 23768 23116 Not Found: /favicon.ico
WARNING 2024-03-26 12:18:20,075 log 23768 9056 Bad Request: /graphql
WARNING 2024-03-26 12:18:20,149 log 23768 23116 Not Found: /media/
WARNING 2024-03-26 12:18:21,664 log 23768 9056 Bad Request: /graphql
WARNING 2024-03-26 12:18:21,744 log 23768 20044 Not Found: /media/
WARNING 2024-03-26 12:18:28,546 log 23768 22240 Bad Request: /graphql
WARNING 2024-03-26 12:18:28,565 log 23768 17396 Not Found: /media/
WARNING 2024-03-26 12:18:53,600 log 23768 22240 Bad Request: /graphql
WARNING 2024-03-26 12:18:56,745 log 23768 22240 Bad Request: /graphql
WARNING 2024-03-26 12:18:56,773 log 23768 22584 Not Found: /media/
WARNING 2024-03-26 12:19:00,996 log 23768 22240 Bad Request: /graphql
WARNING 2024-03-26 12:19:01,080 log 23768 16988 Not Found: /media/
WARNING 2024-03-26 12:19:24,005 log 23768 22240 Bad Request: /graphql
WARNING 2024-03-26 12:19:24,421 log 23768 21940 Not Found: /media/
WARNING 2024-03-26 12:19:47,423 log 23768 22240 Bad Request: /graphql
WARNING 2024-03-26 12:19:50,114 log 23768 22240 Bad Request: /graphql
WARNING 2024-03-26 12:19:50,130 log 23768 9604 Not Found: /media/
WARNING 2024-03-26 12:19:52,970 log 23768 22240 Bad Request: /graphql
WARNING 2024-03-26 12:19:53,385 log 23768 16244 Not Found: /media/
WARNING 2024-03-26 12:19:56,312 log 23768 22240 Bad Request: /graphql
WARNING 2024-03-26 12:19:56,385 log 23768 21868 Not Found: /media/
WARNING 2024-03-26 12:19:57,182 log 23768 22240 Bad Request: /graphql
WARNING 2024-03-26 12:19:57,593 log 23768 12384 Not Found: /media/
WARNING 2024-03-26 12:19:58,806 log 23768 22240 Bad Request: /graphql
WARNING 2024-03-26 12:19:58,877 log 23768 19756 Not Found: /media/
WARNING 2024-03-26 12:20:02,698 log 23768 22240 Bad Request: /graphql
WARNING 2024-03-26 12:20:03,103 log 23768 21948 Not Found: /media/
WARNING 2024-03-26 12:20:06,645 log 23768 3604 Not Found: /favicon.ico
WARNING 2024-03-26 12:20:10,937 log 23768 22240 Bad Request: /graphql
WARNING 2024-03-26 12:20:11,007 log 23768 3604 Not Found: /media/
WARNING 2024-03-26 12:20:22,521 log 23768 22240 Bad Request: /graphql
WARNING 2024-03-26 12:20:22,533 log 23768 10140 Not Found: /media/
WARNING 2024-03-26 12:20:25,051 log 23768 22240 Bad Request: /graphql
WARNING 2024-03-26 12:20:25,440 log 23768 23572 Not Found: /media/
WARNING 2024-03-26 12:20:27,832 log 23768 22240 Bad Request: /graphql
WARNING 2024-03-26 12:20:27,908 log 23768 5572 Not Found: /media/
WARNING 2024-03-26 12:20:57,658 log 23768 22240 Not Found: /api/v1/users/
WARNING 2024-03-26 12:21:42,329 log 23768 22240 Not Found: /api/v1/users/
ERROR 2024-03-26 12:22:41,220 log 22356 22436 Internal Server Error: /api/v1/users/
Traceback (most recent call last):
  File "c:\Users\Sergey Trosenko\DyplomaProductAggregator\.venv\Lib\site-packages\django\core\handlers\exception.py", line 55, in inner
    response = get_response(request)
               ^^^^^^^^^^^^^^^^^^^^^
  File "c:\Users\Sergey Trosenko\DyplomaProductAggregator\.venv\Lib\site-packages\django\core\handlers\base.py", line 197, in _get_response
    response = wrapped_callback(request, *callback_args, **callback_kwargs)
               ^^^^^^^^^^^^^^^^^^^^^^^^^^^^^^^^^^^^^^^^^^^^^^^^^^^^^^^^^^^^
  File "c:\Users\Sergey Trosenko\DyplomaProductAggregator\.venv\Lib\site-packages\django\views\decorators\csrf.py", line 56, in wrapper_view
    return view_func(*args, **kwargs)
           ^^^^^^^^^^^^^^^^^^^^^^^^^^
  File "c:\Users\Sergey Trosenko\DyplomaProductAggregator\.venv\Lib\site-packages\rest_framework\viewsets.py", line 125, in view
    return self.dispatch(request, *args, **kwargs)
           ^^^^^^^^^^^^^^^^^^^^^^^^^^^^^^^^^^^^^^^
  File "c:\Users\Sergey Trosenko\DyplomaProductAggregator\.venv\Lib\site-packages\rest_framework\views.py", line 509, in dispatch
    response = self.handle_exception(exc)
               ^^^^^^^^^^^^^^^^^^^^^^^^^^
  File "c:\Users\Sergey Trosenko\DyplomaProductAggregator\.venv\Lib\site-packages\rest_framework\views.py", line 469, in handle_exception
    self.raise_uncaught_exception(exc)
  File "c:\Users\Sergey Trosenko\DyplomaProductAggregator\.venv\Lib\site-packages\rest_framework\views.py", line 480, in raise_uncaught_exception
    raise exc
  File "c:\Users\Sergey Trosenko\DyplomaProductAggregator\.venv\Lib\site-packages\rest_framework\views.py", line 506, in dispatch
    response = handler(request, *args, **kwargs)
               ^^^^^^^^^^^^^^^^^^^^^^^^^^^^^^^^^
  File "c:\Users\Sergey Trosenko\DyplomaProductAggregator\.venv\Lib\site-packages\rest_framework\mixins.py", line 19, in create
    self.perform_create(serializer)
  File "c:\Users\Sergey Trosenko\DyplomaProductAggregator\.venv\Lib\site-packages\djoser\views.py", line 140, in perform_create
    settings.EMAIL.activation(self.request, context).send(to)
  File "c:\Users\Sergey Trosenko\DyplomaProductAggregator\.venv\Lib\site-packages\templated_mail\mail.py", line 78, in send
    super(BaseEmailMessage, self).send(*args, **kwargs)
  File "c:\Users\Sergey Trosenko\DyplomaProductAggregator\.venv\Lib\site-packages\django\core\mail\message.py", line 298, in send
    return self.get_connection(fail_silently).send_messages([self])
           ^^^^^^^^^^^^^^^^^^^^^^^^^^^^^^^^^^^^^^^^^^^^^^^^^^^^^^^^
  File "c:\Users\Sergey Trosenko\DyplomaProductAggregator\.venv\Lib\site-packages\django\core\mail\backends\smtp.py", line 127, in send_messages
    new_conn_created = self.open()
                       ^^^^^^^^^^^
  File "c:\Users\Sergey Trosenko\DyplomaProductAggregator\.venv\Lib\site-packages\django\core\mail\backends\smtp.py", line 85, in open
    self.connection = self.connection_class(
                      ^^^^^^^^^^^^^^^^^^^^^^
  File "c:\Users\Sergey Trosenko\AppData\Local\Programs\Python\Python312\Lib\smtplib.py", line 255, in __init__
    (code, msg) = self.connect(host, port)
                  ^^^^^^^^^^^^^^^^^^^^^^^^
  File "c:\Users\Sergey Trosenko\AppData\Local\Programs\Python\Python312\Lib\smtplib.py", line 341, in connect
    self.sock = self._get_socket(host, port, self.timeout)
                ^^^^^^^^^^^^^^^^^^^^^^^^^^^^^^^^^^^^^^^^^^
  File "c:\Users\Sergey Trosenko\AppData\Local\Programs\Python\Python312\Lib\smtplib.py", line 312, in _get_socket
    return socket.create_connection((host, port), timeout,
           ^^^^^^^^^^^^^^^^^^^^^^^^^^^^^^^^^^^^^^^^^^^^^^^
  File "c:\Users\Sergey Trosenko\AppData\Local\Programs\Python\Python312\Lib\socket.py", line 852, in create_connection
    raise exceptions[0]
  File "c:\Users\Sergey Trosenko\AppData\Local\Programs\Python\Python312\Lib\socket.py", line 837, in create_connection
    sock.connect(sa)
ConnectionRefusedError: [WinError 10061] Подключение не установлено, т.к. конечный компьютер отверг запрос на подключение
WARNING 2024-03-26 12:22:46,964 log 22356 13088 Not Found: /favicon.ico
WARNING 2024-03-26 12:23:33,346 log 22356 13088 Not Found: /favicon.ico
WARNING 2024-03-26 12:23:51,842 log 22356 23220 Bad Request: /graphql
WARNING 2024-03-26 12:23:58,084 log 22356 23220 Bad Request: /graphql
WARNING 2024-03-26 12:23:58,113 log 22356 13088 Not Found: /media/
WARNING 2024-03-26 12:24:01,534 log 22356 23220 Bad Request: /graphql
WARNING 2024-03-26 12:24:01,916 log 22356 1172 Not Found: /media/
WARNING 2024-03-26 12:24:15,038 log 22356 23220 Bad Request: /graphql
WARNING 2024-03-26 12:24:15,133 log 22356 10544 Not Found: /media/
WARNING 2024-03-26 12:24:16,113 log 22356 23220 Bad Request: /graphql
WARNING 2024-03-26 12:24:16,500 log 22356 14536 Not Found: /media/
WARNING 2024-03-26 12:25:50,188 log 22356 20852 Not Found: /media/
WARNING 2024-03-26 12:25:57,189 log 22356 23768 Not Found: /media/
WARNING 2024-03-26 12:26:19,362 log 22356 14676 Not Found: /media/
WARNING 2024-03-26 12:26:26,408 log 22356 23740 Not Found: /media/
WARNING 2024-03-26 12:26:39,918 log 22356 11884 Not Found: /media/
WARNING 2024-03-26 12:26:41,493 log 22356 22260 Not Found: /media/
WARNING 2024-03-26 12:26:43,097 log 22356 14488 Not Found: /media/
WARNING 2024-03-26 12:26:48,422 log 22356 23724 Not Found: /media/
WARNING 2024-03-26 12:27:54,333 log 5444 7884 Not Found: /media/
WARNING 2024-03-26 12:28:17,239 log 23040 22136 Not Found: /media/
WARNING 2024-03-26 12:29:00,438 log 23040 19844 Not Found: /media/
WARNING 2024-03-26 12:29:04,239 log 23040 5488 Not Found: /media/
WARNING 2024-03-26 12:29:15,964 log 23040 18956 Not Found: /media/
WARNING 2024-03-26 12:29:17,570 log 23040 1520 Not Found: /media/
WARNING 2024-03-26 12:29:46,330 log 23040 3960 Not Found: /media/
WARNING 2024-03-26 12:29:53,477 log 23040 6516 Not Found: /media/
WARNING 2024-03-26 12:30:12,910 log 23040 10040 Not Found: /media/
WARNING 2024-03-26 12:30:15,292 log 23040 2168 Not Found: /media/
WARNING 2024-03-26 12:30:25,082 log 23040 24052 Not Found: /media/
WARNING 2024-03-26 12:31:18,176 log 23040 12396 Not Found: /media/
WARNING 2024-03-26 12:32:01,414 log 23040 12300 Not Found: /media/
WARNING 2024-03-26 12:32:07,722 log 23040 388 Not Found: /media/
WARNING 2024-03-26 12:33:51,121 log 23040 24048 Not Found: /media/
WARNING 2024-03-26 12:34:08,115 log 23040 21860 Not Found: /media/
WARNING 2024-03-26 12:34:46,433 log 23040 8436 Not Found: /media/
WARNING 2024-03-26 12:34:47,615 log 23040 6560 Not Found: /media/
WARNING 2024-03-26 12:34:51,706 log 23040 3736 Not Found: /media/
WARNING 2024-03-26 12:34:53,050 log 23040 22104 Not Found: /media/
WARNING 2024-03-26 12:35:04,909 log 23040 8164 Not Found: /media/
WARNING 2024-03-26 12:35:07,313 log 23040 2528 Not Found: /media/
WARNING 2024-03-26 12:36:18,007 log 23040 22364 Not Found: /media/
WARNING 2024-03-26 12:36:40,864 log 23040 11844 Not Found: /media/
WARNING 2024-03-26 12:36:43,463 log 23040 8516 Not Found: /media/
WARNING 2024-03-28 13:33:55,766 log 44 140224270194432 Not Found: /
WARNING 2024-03-28 13:33:55,919 log 44 140224270194432 Not Found: /favicon.ico
WARNING 2024-03-28 13:39:49,188 log 12 139652970690304 Not Found: /favicon.ico
WARNING 2024-03-28 13:56:49,990 log 34 139871223666432 Bad Request: /graphql
WARNING 2024-03-28 13:57:43,411 log 34 139871232059136 Bad Request: /graphql
WARNING 2024-03-28 13:58:34,856 log 34 139871232059136 Bad Request: /graphql
WARNING 2024-03-28 13:58:41,734 log 34 139871232059136 Bad Request: /graphql
WARNING 2024-03-28 14:00:01,625 log 34 139871202686720 Not Found: /media/https://content.rozetka.com.ua/goods/images/big_tile/370582805.jpg
WARNING 2024-03-28 14:00:01,626 log 34 139870827697920 Not Found: /media/https://content1.rozetka.com.ua/goods/images/big_tile/421474277.jpg
WARNING 2024-03-28 14:00:01,630 log 34 139871211079424 Not Found: /media/https://content.rozetka.com.ua/goods/images/big_tile/421573786.jpg
WARNING 2024-03-28 14:00:01,632 log 34 139870844483328 Not Found: /media/https://content2.rozetka.com.ua/goods/images/big_tile/374584888.jpg
WARNING 2024-03-28 14:00:01,633 log 34 139870836090624 Not Found: /media/https://content1.rozetka.com.ua/goods/images/big_tile/421149133.jpg
WARNING 2024-03-28 14:00:01,635 log 34 139871194294016 Not Found: /media/https://content2.rozetka.com.ua/goods/images/big_tile/374584853.jpg
WARNING 2024-03-28 14:00:06,184 log 34 139870827697920 Not Found: /media/https://content1.rozetka.com.ua/goods/images/big_tile/370582839.jpg
WARNING 2024-03-28 14:00:06,204 log 34 139870844483328 Not Found: /media/https://content2.rozetka.com.ua/goods/images/big_tile/374584856.jpg
WARNING 2024-03-28 14:00:06,231 log 34 139870836090624 Not Found: /media/https://content.rozetka.com.ua/goods/images/big_tile/420635393.jpg
WARNING 2024-03-28 14:00:06,243 log 34 139871194294016 Not Found: /media/https://content2.rozetka.com.ua/goods/images/big_tile/420635398.jpg
WARNING 2024-03-28 14:00:06,270 log 34 139870827697920 Not Found: /media/https://content.rozetka.com.ua/goods/images/big_tile/420762166.jpg
WARNING 2024-03-28 14:00:06,305 log 34 139870844483328 Not Found: /media/https://content2.rozetka.com.ua/goods/images/big_tile/420773048.jpg
WARNING 2024-03-28 14:00:07,267 log 34 139870836090624 Not Found: /media/https://content1.rozetka.com.ua/goods/images/big_tile/420773661.jpg
WARNING 2024-03-28 14:00:07,313 log 34 139871194294016 Not Found: /media/https://content.rozetka.com.ua/goods/images/big_tile/420772676.jpg
WARNING 2024-03-28 14:00:07,319 log 34 139870827697920 Not Found: /media/https://content2.rozetka.com.ua/goods/images/big_tile/420772675.jpg
WARNING 2024-03-28 14:00:07,354 log 34 139870836090624 Not Found: /media/https://content.rozetka.com.ua/goods/images/big_tile/420772679.jpg
WARNING 2024-03-28 14:00:07,356 log 34 139870844483328 Not Found: /media/https://content1.rozetka.com.ua/goods/images/big_tile/420773075.jpg
WARNING 2024-03-28 14:00:07,392 log 34 139871194294016 Not Found: /media/https://content.rozetka.com.ua/goods/images/big_tile/420773080.jpg
WARNING 2024-03-28 14:09:58,492 log 34 139870844483328 Not Found: /aggregator/images/rozetka.png
WARNING 2024-03-28 14:09:58,495 log 34 139870836090624 Not Found: /aggregator/images/rozetka.png
WARNING 2024-03-28 15:42:38,268 log 137 139801348335360 Bad Request: /graphql
WARNING 2024-03-28 15:42:51,207 log 137 139801339942656 Bad Request: /graphql
WARNING 2024-03-28 15:44:54,885 log 137 139801118373632 Bad Request: /graphql
WARNING 2024-03-28 15:45:02,370 log 137 139801118373632 Bad Request: /graphql
WARNING 2024-03-28 15:45:59,710 log 137 139801109980928 Not Found: /media/https://content2.rozetka.com.ua/goods/images/big_tile/374584856.jpg
WARNING 2024-03-28 16:56:16,141 log 169 140068475893504 Not Found: /favicon.ico
WARNING 2024-03-28 17:25:30,532 log 181 140409854486272 Bad Request: /graphql
WARNING 2024-03-28 17:25:55,395 log 181 140409862878976 Bad Request: /graphql
WARNING 2024-03-28 17:25:55,408 log 181 140409854486272 Bad Request: /graphql
WARNING 2024-03-28 17:27:29,425 log 181 140409854486272 Bad Request: /graphql
WARNING 2024-03-28 17:27:29,443 log 181 140409862878976 Bad Request: /graphql
WARNING 2024-03-28 17:29:22,918 log 196 140546330887936 Bad Request: /graphql
WARNING 2024-03-28 17:40:07,804 log 202 139787562383104 Not Found: /media/undefined
WARNING 2024-03-29 12:13:44,966 log 12 140630617466624 Not Found: /favicon.ico
WARNING 2024-03-29 12:16:59,823 log 12 140630617466624 Not Found: /shops
WARNING 2024-03-29 12:17:00,238 log 12 140630617466624 Not Found: /favicon.ico
WARNING 2024-03-29 12:18:56,203 log 12 140630636349184 Bad Request: /graphql
WARNING 2024-03-29 12:18:56,949 log 12 140630636349184 Bad Request: /graphql
WARNING 2024-03-29 12:37:13,457 log 12 139785897830144 Bad Request: /graphql
WARNING 2024-03-29 12:48:07,333 log 12 139919355799296 Not Found: /mediaaggregator/images/tavriav.png
WARNING 2024-03-29 12:48:07,336 log 12 139919709525760 Not Found: /mediaaggregator/images/Silpo_outline_logo.png
WARNING 2024-03-29 12:48:07,341 log 12 139919364192000 Not Found: /mediaaggregator/images/rozetka.png
WARNING 2024-03-29 12:48:44,076 log 12 139919364192000 Not Found: /mediaaggregator/images/Silpo_outline_logo.png
WARNING 2024-03-29 12:48:44,088 log 12 139919709525760 Not Found: /mediaaggregator/images/rozetka.png
WARNING 2024-03-29 12:48:44,092 log 12 139919355799296 Not Found: /mediaaggregator/images/tavriav.png
WARNING 2024-03-29 15:19:45,667 log 12 140235695445760 Not Found: /media/
WARNING 2024-03-29 15:20:05,982 log 12 140235695445760 Not Found: /media/
WARNING 2024-03-29 15:20:19,728 log 12 140235695445760 Not Found: /media/
WARNING 2024-03-29 15:20:33,662 log 12 140235312723712 Bad Request: /graphql
WARNING 2024-03-29 15:20:56,583 log 12 140235695445760 Not Found: /favicon.ico
WARNING 2024-03-29 15:21:22,299 log 12 140235695445760 Not Found: /media/
WARNING 2024-03-29 15:23:01,146 log 12 140235686004480 Not Found: /media/
WARNING 2024-03-29 15:23:05,963 log 12 140235686004480 Not Found: /media/
WARNING 2024-03-29 15:25:00,376 log 12 140235686004480 Not Found: /media/
WARNING 2024-03-29 15:27:30,987 log 12 140235312723712 Bad Request: /graphql
WARNING 2024-03-29 15:28:55,146 log 12 140235677611776 Not Found: /media/
WARNING 2024-03-29 15:29:15,495 log 12 140235677611776 Not Found: /media/
WARNING 2024-03-29 15:29:45,392 log 12 140235677611776 Not Found: /media/
WARNING 2024-03-29 15:30:46,682 log 12 140235677611776 Not Found: /media/
WARNING 2024-03-29 15:30:58,377 log 12 140235677611776 Not Found: /media/
WARNING 2024-03-29 15:31:01,637 log 12 140235677611776 Not Found: /media/
WARNING 2024-03-29 18:43:53,016 log 12 139875957626624 Bad Request: /graphql
WARNING 2024-03-29 18:44:01,884 log 12 139875957626624 Bad Request: /graphql
WARNING 2024-03-29 18:44:31,591 log 12 139875957626624 Bad Request: /graphql
WARNING 2024-03-29 18:44:46,909 log 12 139875957626624 Bad Request: /graphql
WARNING 2024-03-29 18:50:22,177 log 50 140706714781440 Bad Request: /graphql
WARNING 2024-03-29 18:50:28,867 log 50 140706714781440 Bad Request: /graphql
WARNING 2024-03-29 18:51:14,214 log 54 140575399266048 Bad Request: /graphql
WARNING 2024-03-29 18:52:29,724 log 54 140575399266048 Bad Request: /graphql
WARNING 2024-03-29 18:53:53,022 log 59 139978218665728 Bad Request: /graphql
WARNING 2024-03-29 18:54:01,768 log 59 139978218665728 Not Found: /favicon.ico
WARNING 2024-03-29 18:55:12,560 log 59 139978218665728 Bad Request: /graphql
WARNING 2024-03-29 18:55:41,094 log 59 139978218665728 Bad Request: /graphql
WARNING 2024-03-29 19:10:22,995 log 70 140649920419584 Bad Request: /graphql
WARNING 2024-03-30 12:34:58,870 log 12 139824560879360 Not Found: /favicon.ico
WARNING 2024-03-30 15:46:39,400 log 57 140244909291264 Not Found: /favicon.ico
WARNING 2024-03-30 22:18:46,905 log 23740 14740 Not Found: /favicon.ico
WARNING 2024-04-07 09:43:35,983 log 13 140522656093952 Not Found: /favicon.ico
ERROR 2024-04-07 09:45:38,658 log 13 140522664486656 Internal Server Error: /admin/telegram_bot/user/
Traceback (most recent call last):
  File "/usr/local/lib/python3.10/site-packages/django/db/backends/utils.py", line 89, in _execute
    return self.cursor.execute(sql, params)
psycopg2.errors.UndefinedColumn: column telegram_bot_user.send_products does not exist
LINE 1: ..."."created_at", "telegram_bot_user"."updated_at", "telegram_...
                                                             ^


The above exception was the direct cause of the following exception:

Traceback (most recent call last):
  File "/usr/local/lib/python3.10/site-packages/django/core/handlers/exception.py", line 55, in inner
    response = get_response(request)
  File "/usr/local/lib/python3.10/site-packages/django/core/handlers/base.py", line 197, in _get_response
    response = wrapped_callback(request, *callback_args, **callback_kwargs)
  File "/usr/local/lib/python3.10/site-packages/django/contrib/admin/options.py", line 688, in wrapper
    return self.admin_site.admin_view(view)(*args, **kwargs)
  File "/usr/local/lib/python3.10/site-packages/django/utils/decorators.py", line 134, in _wrapper_view
    response = view_func(request, *args, **kwargs)
  File "/usr/local/lib/python3.10/site-packages/django/views/decorators/cache.py", line 62, in _wrapper_view_func
    response = view_func(request, *args, **kwargs)
  File "/usr/local/lib/python3.10/site-packages/django/contrib/admin/sites.py", line 242, in inner
    return view(request, *args, **kwargs)
  File "/usr/local/lib/python3.10/site-packages/django/utils/decorators.py", line 46, in _wrapper
    return bound_method(*args, **kwargs)
  File "/usr/local/lib/python3.10/site-packages/django/utils/decorators.py", line 134, in _wrapper_view
    response = view_func(request, *args, **kwargs)
  File "/usr/local/lib/python3.10/site-packages/django/contrib/admin/options.py", line 2065, in changelist_view
    "selection_note": _("0 of %(cnt)s selected") % {"cnt": len(cl.result_list)},
  File "/usr/local/lib/python3.10/site-packages/django/db/models/query.py", line 380, in __len__
    self._fetch_all()
  File "/usr/local/lib/python3.10/site-packages/django/db/models/query.py", line 1881, in _fetch_all
    self._result_cache = list(self._iterable_class(self))
  File "/usr/local/lib/python3.10/site-packages/django/db/models/query.py", line 91, in __iter__
    results = compiler.execute_sql(
  File "/usr/local/lib/python3.10/site-packages/django/db/models/sql/compiler.py", line 1560, in execute_sql
    cursor.execute(sql, params)
  File "/usr/local/lib/python3.10/site-packages/django/db/backends/utils.py", line 102, in execute
    return super().execute(sql, params)
  File "/usr/local/lib/python3.10/site-packages/django/db/backends/utils.py", line 67, in execute
    return self._execute_with_wrappers(
  File "/usr/local/lib/python3.10/site-packages/django/db/backends/utils.py", line 80, in _execute_with_wrappers
    return executor(sql, params, many, context)
  File "/usr/local/lib/python3.10/site-packages/django/db/backends/utils.py", line 84, in _execute
    with self.db.wrap_database_errors:
  File "/usr/local/lib/python3.10/site-packages/django/db/utils.py", line 91, in __exit__
    raise dj_exc_value.with_traceback(traceback) from exc_value
  File "/usr/local/lib/python3.10/site-packages/django/db/backends/utils.py", line 89, in _execute
    return self.cursor.execute(sql, params)
django.db.utils.ProgrammingError: column telegram_bot_user.send_products does not exist
LINE 1: ..."."created_at", "telegram_bot_user"."updated_at", "telegram_...
                                                             ^

ERROR 2024-04-07 09:50:03,637 log 13 140522672879360 Internal Server Error: /admin/telegram_bot/user/
Traceback (most recent call last):
  File "/usr/local/lib/python3.10/site-packages/django/db/backends/utils.py", line 89, in _execute
    return self.cursor.execute(sql, params)
psycopg2.errors.UndefinedColumn: column telegram_bot_user.send_products does not exist
LINE 1: ..."."created_at", "telegram_bot_user"."updated_at", "telegram_...
                                                             ^


The above exception was the direct cause of the following exception:

Traceback (most recent call last):
  File "/usr/local/lib/python3.10/site-packages/django/core/handlers/exception.py", line 55, in inner
    response = get_response(request)
  File "/usr/local/lib/python3.10/site-packages/django/core/handlers/base.py", line 197, in _get_response
    response = wrapped_callback(request, *callback_args, **callback_kwargs)
  File "/usr/local/lib/python3.10/site-packages/django/contrib/admin/options.py", line 688, in wrapper
    return self.admin_site.admin_view(view)(*args, **kwargs)
  File "/usr/local/lib/python3.10/site-packages/django/utils/decorators.py", line 134, in _wrapper_view
    response = view_func(request, *args, **kwargs)
  File "/usr/local/lib/python3.10/site-packages/django/views/decorators/cache.py", line 62, in _wrapper_view_func
    response = view_func(request, *args, **kwargs)
  File "/usr/local/lib/python3.10/site-packages/django/contrib/admin/sites.py", line 242, in inner
    return view(request, *args, **kwargs)
  File "/usr/local/lib/python3.10/site-packages/django/utils/decorators.py", line 46, in _wrapper
    return bound_method(*args, **kwargs)
  File "/usr/local/lib/python3.10/site-packages/django/utils/decorators.py", line 134, in _wrapper_view
    response = view_func(request, *args, **kwargs)
  File "/usr/local/lib/python3.10/site-packages/django/contrib/admin/options.py", line 2065, in changelist_view
    "selection_note": _("0 of %(cnt)s selected") % {"cnt": len(cl.result_list)},
  File "/usr/local/lib/python3.10/site-packages/django/db/models/query.py", line 380, in __len__
    self._fetch_all()
  File "/usr/local/lib/python3.10/site-packages/django/db/models/query.py", line 1881, in _fetch_all
    self._result_cache = list(self._iterable_class(self))
  File "/usr/local/lib/python3.10/site-packages/django/db/models/query.py", line 91, in __iter__
    results = compiler.execute_sql(
  File "/usr/local/lib/python3.10/site-packages/django/db/models/sql/compiler.py", line 1560, in execute_sql
    cursor.execute(sql, params)
  File "/usr/local/lib/python3.10/site-packages/django/db/backends/utils.py", line 102, in execute
    return super().execute(sql, params)
  File "/usr/local/lib/python3.10/site-packages/django/db/backends/utils.py", line 67, in execute
    return self._execute_with_wrappers(
  File "/usr/local/lib/python3.10/site-packages/django/db/backends/utils.py", line 80, in _execute_with_wrappers
    return executor(sql, params, many, context)
  File "/usr/local/lib/python3.10/site-packages/django/db/backends/utils.py", line 84, in _execute
    with self.db.wrap_database_errors:
  File "/usr/local/lib/python3.10/site-packages/django/db/utils.py", line 91, in __exit__
    raise dj_exc_value.with_traceback(traceback) from exc_value
  File "/usr/local/lib/python3.10/site-packages/django/db/backends/utils.py", line 89, in _execute
    return self.cursor.execute(sql, params)
django.db.utils.ProgrammingError: column telegram_bot_user.send_products does not exist
LINE 1: ..."."created_at", "telegram_bot_user"."updated_at", "telegram_...
                                                             ^

WARNING 2024-04-07 10:07:49,339 log 13 139817375975168 Not Found: /favicon.ico
ERROR 2024-04-07 10:07:56,306 log 13 139817420035840 Internal Server Error: /admin/telegram_bot/user/
Traceback (most recent call last):
  File "/usr/local/lib/python3.10/site-packages/django/db/backends/utils.py", line 89, in _execute
    return self.cursor.execute(sql, params)
psycopg2.errors.UndefinedColumn: column telegram_bot_user.send_products does not exist
LINE 1: ..."."created_at", "telegram_bot_user"."updated_at", "telegram_...
                                                             ^


The above exception was the direct cause of the following exception:

Traceback (most recent call last):
  File "/usr/local/lib/python3.10/site-packages/django/core/handlers/exception.py", line 55, in inner
    response = get_response(request)
  File "/usr/local/lib/python3.10/site-packages/django/core/handlers/base.py", line 197, in _get_response
    response = wrapped_callback(request, *callback_args, **callback_kwargs)
  File "/usr/local/lib/python3.10/site-packages/django/contrib/admin/options.py", line 688, in wrapper
    return self.admin_site.admin_view(view)(*args, **kwargs)
  File "/usr/local/lib/python3.10/site-packages/django/utils/decorators.py", line 134, in _wrapper_view
    response = view_func(request, *args, **kwargs)
  File "/usr/local/lib/python3.10/site-packages/django/views/decorators/cache.py", line 62, in _wrapper_view_func
    response = view_func(request, *args, **kwargs)
  File "/usr/local/lib/python3.10/site-packages/django/contrib/admin/sites.py", line 242, in inner
    return view(request, *args, **kwargs)
  File "/usr/local/lib/python3.10/site-packages/django/utils/decorators.py", line 46, in _wrapper
    return bound_method(*args, **kwargs)
  File "/usr/local/lib/python3.10/site-packages/django/utils/decorators.py", line 134, in _wrapper_view
    response = view_func(request, *args, **kwargs)
  File "/usr/local/lib/python3.10/site-packages/django/contrib/admin/options.py", line 2065, in changelist_view
    "selection_note": _("0 of %(cnt)s selected") % {"cnt": len(cl.result_list)},
  File "/usr/local/lib/python3.10/site-packages/django/db/models/query.py", line 380, in __len__
    self._fetch_all()
  File "/usr/local/lib/python3.10/site-packages/django/db/models/query.py", line 1881, in _fetch_all
    self._result_cache = list(self._iterable_class(self))
  File "/usr/local/lib/python3.10/site-packages/django/db/models/query.py", line 91, in __iter__
    results = compiler.execute_sql(
  File "/usr/local/lib/python3.10/site-packages/django/db/models/sql/compiler.py", line 1560, in execute_sql
    cursor.execute(sql, params)
  File "/usr/local/lib/python3.10/site-packages/django/db/backends/utils.py", line 102, in execute
    return super().execute(sql, params)
  File "/usr/local/lib/python3.10/site-packages/django/db/backends/utils.py", line 67, in execute
    return self._execute_with_wrappers(
  File "/usr/local/lib/python3.10/site-packages/django/db/backends/utils.py", line 80, in _execute_with_wrappers
    return executor(sql, params, many, context)
  File "/usr/local/lib/python3.10/site-packages/django/db/backends/utils.py", line 84, in _execute
    with self.db.wrap_database_errors:
  File "/usr/local/lib/python3.10/site-packages/django/db/utils.py", line 91, in __exit__
    raise dj_exc_value.with_traceback(traceback) from exc_value
  File "/usr/local/lib/python3.10/site-packages/django/db/backends/utils.py", line 89, in _execute
    return self.cursor.execute(sql, params)
django.db.utils.ProgrammingError: column telegram_bot_user.send_products does not exist
LINE 1: ..."."created_at", "telegram_bot_user"."updated_at", "telegram_...
                                                             ^

ERROR 2024-04-07 10:08:46,458 log 41 140236118030080 Internal Server Error: /admin/telegram_bot/user/
Traceback (most recent call last):
  File "/usr/local/lib/python3.10/site-packages/django/db/backends/utils.py", line 89, in _execute
    return self.cursor.execute(sql, params)
psycopg2.errors.UndefinedColumn: column telegram_bot_user.send_products does not exist
LINE 1: ..."."created_at", "telegram_bot_user"."updated_at", "telegram_...
                                                             ^


The above exception was the direct cause of the following exception:

Traceback (most recent call last):
  File "/usr/local/lib/python3.10/site-packages/django/core/handlers/exception.py", line 55, in inner
    response = get_response(request)
  File "/usr/local/lib/python3.10/site-packages/django/core/handlers/base.py", line 197, in _get_response
    response = wrapped_callback(request, *callback_args, **callback_kwargs)
  File "/usr/local/lib/python3.10/site-packages/django/contrib/admin/options.py", line 688, in wrapper
    return self.admin_site.admin_view(view)(*args, **kwargs)
  File "/usr/local/lib/python3.10/site-packages/django/utils/decorators.py", line 134, in _wrapper_view
    response = view_func(request, *args, **kwargs)
  File "/usr/local/lib/python3.10/site-packages/django/views/decorators/cache.py", line 62, in _wrapper_view_func
    response = view_func(request, *args, **kwargs)
  File "/usr/local/lib/python3.10/site-packages/django/contrib/admin/sites.py", line 242, in inner
    return view(request, *args, **kwargs)
  File "/usr/local/lib/python3.10/site-packages/django/utils/decorators.py", line 46, in _wrapper
    return bound_method(*args, **kwargs)
  File "/usr/local/lib/python3.10/site-packages/django/utils/decorators.py", line 134, in _wrapper_view
    response = view_func(request, *args, **kwargs)
  File "/usr/local/lib/python3.10/site-packages/django/contrib/admin/options.py", line 2065, in changelist_view
    "selection_note": _("0 of %(cnt)s selected") % {"cnt": len(cl.result_list)},
  File "/usr/local/lib/python3.10/site-packages/django/db/models/query.py", line 380, in __len__
    self._fetch_all()
  File "/usr/local/lib/python3.10/site-packages/django/db/models/query.py", line 1881, in _fetch_all
    self._result_cache = list(self._iterable_class(self))
  File "/usr/local/lib/python3.10/site-packages/django/db/models/query.py", line 91, in __iter__
    results = compiler.execute_sql(
  File "/usr/local/lib/python3.10/site-packages/django/db/models/sql/compiler.py", line 1560, in execute_sql
    cursor.execute(sql, params)
  File "/usr/local/lib/python3.10/site-packages/django/db/backends/utils.py", line 102, in execute
    return super().execute(sql, params)
  File "/usr/local/lib/python3.10/site-packages/django/db/backends/utils.py", line 67, in execute
    return self._execute_with_wrappers(
  File "/usr/local/lib/python3.10/site-packages/django/db/backends/utils.py", line 80, in _execute_with_wrappers
    return executor(sql, params, many, context)
  File "/usr/local/lib/python3.10/site-packages/django/db/backends/utils.py", line 84, in _execute
    with self.db.wrap_database_errors:
  File "/usr/local/lib/python3.10/site-packages/django/db/utils.py", line 91, in __exit__
    raise dj_exc_value.with_traceback(traceback) from exc_value
  File "/usr/local/lib/python3.10/site-packages/django/db/backends/utils.py", line 89, in _execute
    return self.cursor.execute(sql, params)
django.db.utils.ProgrammingError: column telegram_bot_user.send_products does not exist
LINE 1: ..."."created_at", "telegram_bot_user"."updated_at", "telegram_...
                                                             ^

WARNING 2024-04-07 12:13:34,179 log 13 139823549802240 Bad Request: /graphql
WARNING 2024-04-07 12:13:51,898 log 13 139823571830528 Bad Request: /graphql
WARNING 2024-04-07 12:13:58,093 log 13 139823571830528 Bad Request: /graphql
WARNING 2024-04-07 12:13:59,093 log 13 139823571830528 Bad Request: /graphql
WARNING 2024-04-07 12:14:00,055 log 13 139823580223232 Bad Request: /graphql
WARNING 2024-04-07 12:14:12,664 log 13 139823580223232 Bad Request: /graphql
WARNING 2024-04-07 12:16:47,463 log 13 139823549802240 Bad Request: /graphql
WARNING 2024-04-07 12:16:53,126 log 13 139823195092736 Bad Request: /graphql
WARNING 2024-04-07 12:17:09,592 log 13 139823549802240 Bad Request: /graphql
WARNING 2024-04-07 12:17:11,267 log 13 139823178307328 Bad Request: /graphql
WARNING 2024-04-07 12:17:11,753 log 13 139823195092736 Bad Request: /graphql
WARNING 2024-04-07 12:17:12,593 log 13 139823178307328 Bad Request: /graphql
WARNING 2024-04-07 12:18:41,348 log 58 140461625689856 Bad Request: /graphql
WARNING 2024-04-07 12:18:55,546 log 58 140461625689856 Bad Request: /graphql
WARNING 2024-04-07 14:19:34,277 log 77 139694012626688 Not Found: /favicon.ico
WARNING 2024-04-07 14:19:53,305 log 77 139694578841344 Not Found: /favicon.ico
WARNING 2024-04-07 14:22:50,141 log 77 139694012626688 Not Found: /favicon.ico
WARNING 2024-04-07 14:23:11,117 log 77 139694562055936 Not Found: /favicon.ico
WARNING 2024-04-07 14:23:30,432 log 77 139694570448640 Not Found: /favicon.ico
WARNING 2024-04-07 14:24:08,779 log 77 139694570448640 Not Found: /favicon.ico
WARNING 2024-04-07 14:28:07,307 log 77 139694596675328 Not Found: /favicon.ico
WARNING 2024-04-07 14:29:13,504 log 77 139694570448640 Not Found: /favicon.ico
WARNING 2024-04-07 14:29:32,624 log 77 139694570448640 Not Found: /favicon.ico
WARNING 2024-04-07 14:30:26,304 log 77 139694562055936 Not Found: /favicon.ico
WARNING 2024-04-07 14:30:47,132 log 77 139694012626688 Not Found: /favicon.ico
WARNING 2024-04-07 15:26:47,252 log 13 140521617770240 Not Found: /favicon.ico
WARNING 2024-04-07 17:34:46,359 log 13 140396345673472 Not Found: /favicon.ico
WARNING 2024-04-07 17:48:25,965 log 84 140117993842432 Not Found: /favicon.ico
